Workbook

Sheet Summary
B2: SYMBOL LIST | E2: LINE PAYS
B3: SYMBOL | C3: 3 | D3: 4 | E3: 5 | F3: LinePay
B4: P1 | C4: 50 | D4: 200 | E4: 1000 | F4: TRUE | I4: Normal play
B5: P2 | C5: 20 | D5: 100 | E5: 500 | F5: TRUE | I5: TYPE | J5: RTP
B6: P3 | C6: 10 | D6: 50 | E6: 250 | F6: TRUE | I6: BASE line | J6: =Summary_calculations!C13 -> 0.52748575
B7: P4 | C7: 5 | D7: 25 | E7: 100 | F7: TRUE | I7: BASE bonus | J7: =Summary_calculations!C14 -> 0.10871435
B8: P5 | C8: 5 | D8: 25 | E8: 100 | F8: TRUE | I8: FREESPINS | J8: =Summary_calculations!C19 -> 0.32408664
B9: P6 | C9: 5 | D9: 25 | E9: 100 | F9: TRUE | I9: TOTAL | J9: =SUM(J6:J8) -> 0.96028674
B10: CP | C10: / | D10: / | E10: / | F10: FALSE
B11: WILD | C11: 0 | D11: 0 | E11: 0 | F11: FALSE
B12: SCAT | C12: 0 | D12: 0 | E12: 0 | F12: FALSE
E14: MULTIPLIER | F14: =C17 -> 20
B17: PAYLINES | C17: =COUNTIF(B18:B117,"<>") -> 20 | E17: REEL WINDOW | F17: Reels | G17: 5
B18: 11111 | F18: Rows | G18: 3
B19: 00000
B20: 22222
B21: 01210 | E21: CP options
B22: 21012 | E22: 0.2
B23: 00100 | E23: 0.5
B24: 22122 | E24: 1
B25: 12221 | E25: 2
B26: 10001 | E26: 3
B27: 01110 | E27: 5
B28: 21112 | E28: 10
B29: 01010 | E29: 25
B30: 21212 | E30: 50
B31: 10101 | E31: 100
B32: 12121
B33: 11011
B34: 11211
B35: 02020
B36: 20202
B37: 10201

Sheet Summary_calculations
C2: ReelSet0 | D2: ReelSet1
A3: =SUM(C3:M3) -> 365 | B3: Weight | C3: 250 | D3: 115
B4: Probability line | C4: =ReelSet0!U36*C$3/$A$3 -> 0.35831544 | D4: =ReelSet1!U36*D$3/$A$3 -> 0.19251084
B5: Probability freespins | C5: =ReelSet0!U37*C$3/$A$3 -> 0 | D5: =ReelSet1!U37*D$3/$A$3 -> 0.0084044204
B6: RTP line | C6: =ReelSet0!U38*C$3/$A$3 -> 0.33967024 | D6: =ReelSet1!U38*D$3/$A$3 -> 0.18781551
B7: RTP bonus | C7: =ReelSet0!U39*C$3/$A$3 -> 0.10817133 | D7: =ReelSet1!U39*D$3/$A$3 -> 0.0005430221
B8: RTP freespins | C8: =ReelSet0!U40*C$3/$A$3 -> 0.074839028 | D8: =ReelSet1!U40*D$3/$A$3 -> 0.24924761
B9: Total RTP | C9: =ReelSet0!U41*C$3/$A$3 -> 0.5226806 | D9: =ReelSet1!U41*D$3/$A$3 -> 0.43760614
B12: Probability base | C12: 1
B13: RTP line | C13: =SUM(C6:F6) -> 0.52748575
B14: RTP bonus | C14: =SUM(C7:F7) -> 0.10871435
B15: Base RTP | C15: =SUM(C13:C14)*C12 -> 0.6362001
B17: Probability trigger | C17: =SUM(C5:F5) -> 0.0084044204
B18: Probability hitrate | C18: =1/C17 -> 118.985
B19: Freespins RTP | C19: =SUM(C8:F8) -> 0.32408664
B21: RTP | C21: =C15+C19 -> 0.96028674

Sheet BaseBonus
C2: Bonus symbol pool
B3: Number of CP on window | C3: 0.5 | D3: 1 | E3: 2 | F3: 3 | G3: 5 | H3: 10 | I3: 15 | J3: 25 | K3: 50 | L3: 100 | M3: 250 | N3: 500 | O3: Average | P3: Awards | Q3: Payout
B4: 0 | C4: 0 | D4: 0 | E4: 0 | F4: 0 | G4: 0 | H4: 0 | I4: 0 | J4: 0 | K4: 0 | L4: 0 | M4: 0 | N4: 0 | O4: =SUMPRODUCT($C$3:$N$3,C4:N4)/SUM(C4:N4) -> #DIV/0! | P4: =B4*O4 -> #DIV/0! | Q4: =IF(B4>=$C$16,TRUE,FALSE) -> FALSE
B5: 1 | C5: 4000 | D5: 5000 | E5: 4500 | F5: 2750 | G5: 1250 | H5: 450 | I5: 100 | J5: 75 | K5: 50 | L5: 20 | M5: 10 | N5: 1 | O5: =SUMPRODUCT($C$3:$N$3,C5:N5)/SUM(C5:N5) -> 2.5197737 | P5: =B5*O5 -> 2.5197737 | Q5: =IF(B5>=$C$16,TRUE,FALSE) -> FALSE
B6: 2 | C6: 4000 | D6: 5000 | E6: 4500 | F6: 2750 | G6: 1250 | H6: 450 | I6: 100 | J6: 75 | K6: 50 | L6: 20 | M6: 10 | N6: 1 | O6: =SUMPRODUCT($C$3:$N$3,C6:N6)/SUM(C6:N6) -> 2.5197737 | P6: =B6*O6 -> 5.0395474 | Q6: =IF(B6>=$C$16,TRUE,FALSE) -> FALSE
B7: 3 | C7: 4500 | D7: 5000 | E7: 4500 | F7: 2750 | G7: 1250 | H7: 450 | I7: 100 | J7: 75 | K7: 50 | L7: 10 | M7: 5 | N7: 1 | O7: =SUMPRODUCT($C$3:$N$3,C7:N7)/SUM(C7:N7) -> 2.3473864 | P7: =B7*O7 -> 7.0421593 | Q7: =IF(B7>=$C$16,TRUE,FALSE) -> FALSE
B8: 4 | C8: 4500 | D8: 5000 | E8: 4500 | F8: 2750 | G8: 1250 | H8: 450 | I8: 100 | J8: 75 | K8: 50 | L8: 10 | M8: 5 | N8: 1 | O8: =SUMPRODUCT($C$3:$N$3,C8:N8)/SUM(C8:N8) -> 2.3473864 | P8: =B8*O8 -> 9.3895458 | Q8: =IF(B8>=$C$16,TRUE,FALSE) -> FALSE
B9: 5 | C9: 6500 | D9: 6500 | E9: 6000 | F9: 3500 | G9: 1500 | H9: 500 | I9: 100 | J9: 75 | K9: 30 | L9: 10 | M9: 5 | N9: 2 | O9: =SUMPRODUCT($C$3:$N$3,C9:N9)/SUM(C9:N9) -> 2.1387833 | P9: =B9*O9 -> 10.693916 | Q9: =IF(B9>=$C$16,TRUE,FALSE) -> TRUE
B10: 6 | C10: 6500 | D10: 6500 | E10: 6000 | F10: 3500 | G10: 1500 | H10: 500 | I10: 100 | J10: 75 | K10: 30 | L10: 10 | M10: 5 | N10: 2 | O10: =SUMPRODUCT($C$3:$N$3,C10:N10)/SUM(C10:N10) -> 2.1387833 | P10: =B10*O10 -> 12.8327 | Q10: =IF(B10>=$C$16,TRUE,FALSE) -> TRUE
B11: 7 | C11: 7250 | D11: 7250 | E11: 5500 | F11: 3000 | G11: 1000 | H11: 500 | I11: 100 | J11: 75 | K11: 30 | L11: 10 | M11: 2 | N11: 1 | O11: =SUMPRODUCT($C$3:$N$3,C11:N11)/SUM(C11:N11) -> 1.9317906 | P11: =B11*O11 -> 13.522534 | Q11: =IF(B11>=$C$16,TRUE,FALSE) -> TRUE
B12: 8 | C12: 7250 | D12: 7250 | E12: 5500 | F12: 3000 | G12: 1000 | H12: 500 | I12: 100 | J12: 75 | K12: 30 | L12: 10 | M12: 2 | N12: 1 | O12: =SUMPRODUCT($C$3:$N$3,C12:N12)/SUM(C12:N12) -> 1.9317906 | P12: =B12*O12 -> 15.454325 | Q12: =IF(B12>=$C$16,TRUE,FALSE) -> TRUE
B13: 9 | C13: 7250 | D13: 7250 | E13: 4750 | F13: 2250 | G13: 1000 | H13: 500 | I13: 100 | J13: 75 | K13: 20 | L13: 5 | M13: 1 | N13: 1 | O13: =SUMPRODUCT($C$3:$N$3,C13:N13)/SUM(C13:N13) -> 1.8425136 | P13: =B13*O13 -> 16.582622 | Q13: =IF(B13>=$C$16,TRUE,FALSE) -> TRUE
B14: 10 | C14: 7250 | D14: 7250 | E14: 4750 | F14: 2250 | G14: 1000 | H14: 500 | I14: 100 | J14: 75 | K14: 20 | L14: 5 | M14: 1 | N14: 1 | O14: =SUMPRODUCT($C$3:$N$3,C14:N14)/SUM(C14:N14) -> 1.8425136 | P14: =B14*O14 -> 18.425136 | Q14: =IF(B14>=$C$16,TRUE,FALSE) -> TRUE
B16: Bonus threshold | C16: 5
C20: Weight | D20: Probability | E20: RTP
B21: =Summary!E22 -> 0.2 | C21: 30000 | D21: =C21/SUM($C$21:$C$30) -> 0.55238446 | E21: =D21*B21 -> 0.11047689
B22: =Summary!E23 -> 0.5 | C22: 10000 | D22: =C22/SUM($C$21:$C$30) -> 0.18412815 | E22: =D22*B22 -> 0.092064077
B23: =Summary!E24 -> 1 | C23: 8000 | D23: =C23/SUM($C$21:$C$30) -> 0.14730252 | E23: =D23*B23 -> 0.14730252
B24: =Summary!E25 -> 2 | C24: 2500 | D24: =C24/SUM($C$21:$C$30) -> 0.046032038 | E24: =D24*B24 -> 0.092064077
B25: =Summary!E26 -> 3 | C25: 2000 | D25: =C25/SUM($C$21:$C$30) -> 0.036825631 | E25: =D25*B25 -> 0.11047689
B26: =Summary!E27 -> 5 | C26: 1000 | D26: =C26/SUM($C$21:$C$30) -> 0.018412815 | E26: =D26*B26 -> 0.092064077
B27: =Summary!E28 -> 10 | C27: 500 | D27: =C27/SUM($C$21:$C$30) -> 0.0092064077 | E27: =D27*B27 -> 0.092064077
B28: =Summary!E29 -> 25 | C28: 200 | D28: =C28/SUM($C$21:$C$30) -> 0.0036825631 | E28: =D28*B28 -> 0.092064077
B29: =Summary!E30 -> 50 | C29: 100 | D29: =C29/SUM($C$21:$C$30) -> 0.0018412815 | E29: =D29*B29 -> 0.092064077
B30: =Summary!E31 -> 100 | C30: 10 | D30: =C30/SUM($C$21:$C$30) -> 0.00018412815 | E30: =D30*B30 -> 0.018412815
E31: =SUM(E21:E30) -> 0.93905358

Sheet FreeSpinsBonus
C2: Bonus symbol pool
B3: Number of CP on window | C3: 0.5 | D3: 1 | E3: 2 | F3: 3 | G3: 5 | H3: 10 | I3: 15 | J3: 25 | K3: 50 | L3: 100 | M3: 250 | N3: 500 | O3: Average | P3: Awards | Q3: Payout
B4: 0 | C4: 0 | D4: 0 | E4: 0 | F4: 0 | G4: 0 | H4: 0 | I4: 0 | J4: 0 | K4: 0 | L4: 0 | M4: 0 | N4: 0 | O4: =SUMPRODUCT($C$3:$N$3,C4:N4)/SUM(C4:N4) -> #DIV/0! | P4: =B4*O4 -> #DIV/0! | Q4: =IF(B4>=$C$16,TRUE,FALSE) -> FALSE
B5: 1 | C5: 4000 | D5: 5000 | E5: 4500 | F5: 2750 | G5: 1250 | H5: 450 | I5: 100 | J5: 75 | K5: 50 | L5: 20 | M5: 10 | N5: 1 | O5: =SUMPRODUCT($C$3:$N$3,C5:N5)/SUM(C5:N5) -> 2.5197737 | P5: =B5*O5 -> 2.5197737 | Q5: =IF(B5>=$C$16,TRUE,FALSE) -> FALSE
B6: 2 | C6: 4000 | D6: 5000 | E6: 4500 | F6: 2750 | G6: 1250 | H6: 450 | I6: 100 | J6: 75 | K6: 50 | L6: 20 | M6: 10 | N6: 1 | O6: =SUMPRODUCT($C$3:$N$3,C6:N6)/SUM(C6:N6) -> 2.5197737 | P6: =B6*O6 -> 5.0395474 | Q6: =IF(B6>=$C$16,TRUE,FALSE) -> FALSE
B7: 3 | C7: 4500 | D7: 5000 | E7: 4500 | F7: 2750 | G7: 1250 | H7: 450 | I7: 100 | J7: 75 | K7: 50 | L7: 10 | M7: 5 | N7: 1 | O7: =SUMPRODUCT($C$3:$N$3,C7:N7)/SUM(C7:N7) -> 2.3473864 | P7: =B7*O7 -> 7.0421593 | Q7: =IF(B7>=$C$16,TRUE,FALSE) -> FALSE
B8: 4 | C8: 4500 | D8: 5000 | E8: 4500 | F8: 2750 | G8: 1250 | H8: 450 | I8: 100 | J8: 75 | K8: 50 | L8: 10 | M8: 5 | N8: 1 | O8: =SUMPRODUCT($C$3:$N$3,C8:N8)/SUM(C8:N8) -> 2.3473864 | P8: =B8*O8 -> 9.3895458 | Q8: =IF(B8>=$C$16,TRUE,FALSE) -> FALSE
B9: 5 | C9: 6500 | D9: 6500 | E9: 6000 | F9: 3500 | G9: 1500 | H9: 500 | I9: 100 | J9: 75 | K9: 30 | L9: 10 | M9: 5 | N9: 2 | O9: =SUMPRODUCT($C$3:$N$3,C9:N9)/SUM(C9:N9) -> 2.1387833 | P9: =B9*O9 -> 10.693916 | Q9: =IF(B9>=$C$16,TRUE,FALSE) -> TRUE
B10: 6 | C10: 6500 | D10: 6500 | E10: 6000 | F10: 3500 | G10: 1500 | H10: 500 | I10: 100 | J10: 75 | K10: 30 | L10: 10 | M10: 5 | N10: 2 | O10: =SUMPRODUCT($C$3:$N$3,C10:N10)/SUM(C10:N10) -> 2.1387833 | P10: =B10*O10 -> 12.8327 | Q10: =IF(B10>=$C$16,TRUE,FALSE) -> TRUE
B11: 7 | C11: 7250 | D11: 7250 | E11: 5500 | F11: 3000 | G11: 1000 | H11: 500 | I11: 100 | J11: 75 | K11: 30 | L11: 10 | M11: 2 | N11: 1 | O11: =SUMPRODUCT($C$3:$N$3,C11:N11)/SUM(C11:N11) -> 1.9317906 | P11: =B11*O11 -> 13.522534 | Q11: =IF(B11>=$C$16,TRUE,FALSE) -> TRUE
B12: 8 | C12: 7250 | D12: 7250 | E12: 5500 | F12: 3000 | G12: 1000 | H12: 500 | I12: 100 | J12: 75 | K12: 30 | L12: 10 | M12: 2 | N12: 1 | O12: =SUMPRODUCT($C$3:$N$3,C12:N12)/SUM(C12:N12) -> 1.9317906 | P12: =B12*O12 -> 15.454325 | Q12: =IF(B12>=$C$16,TRUE,FALSE) -> TRUE
B13: 9 | C13: 7250 | D13: 7250 | E13: 4750 | F13: 2250 | G13: 1000 | H13: 500 | I13: 100 | J13: 75 | K13: 20 | L13: 5 | M13: 1 | N13: 1 | O13: =SUMPRODUCT($C$3:$N$3,C13:N13)/SUM(C13:N13) -> 1.8425136 | P13: =B13*O13 -> 16.582622 | Q13: =IF(B13>=$C$16,TRUE,FALSE) -> TRUE
B14: 10 | C14: 7250 | D14: 7250 | E14: 4750 | F14: 2250 | G14: 1000 | H14: 500 | I14: 100 | J14: 75 | K14: 20 | L14: 5 | M14: 1 | N14: 1 | O14: =SUMPRODUCT($C$3:$N$3,C14:N14)/SUM(C14:N14) -> 1.8425136 | P14: =B14*O14 -> 18.425136 | Q14: =IF(B14>=$C$16,TRUE,FALSE) -> TRUE
B16: Bonus threshold | C16: 5
C20: Weight | D20: Probability | E20: RTP
B21: =Summary!E22 -> 0.2 | C21: 0 | D21: =C21/SUM($C$21:$C$30) -> 0 | E21: =D21*B21 -> 0
B22: =Summary!E23 -> 0.5 | C22: 20000 | D22: =C22/SUM($C$21:$C$30) -> 0.58292043 | E22: =D22*B22 -> 0.29146022
B23: =Summary!E24 -> 1 | C23: 8000 | D23: =C23/SUM($C$21:$C$30) -> 0.23316817 | E23: =D23*B23 -> 0.23316817
B24: =Summary!E25 -> 2 | C24: 2500 | D24: =C24/SUM($C$21:$C$30) -> 0.072865054 | E24: =D24*B24 -> 0.14573011
B25: =Summary!E26 -> 3 | C25: 2000 | D25: =C25/SUM($C$21:$C$30) -> 0.058292043 | E25: =D25*B25 -> 0.17487613
B26: =Summary!E27 -> 5 | C26: 1000 | D26: =C26/SUM($C$21:$C$30) -> 0.029146022 | E26: =D26*B26 -> 0.14573011
B27: =Summary!E28 -> 10 | C27: 500 | D27: =C27/SUM($C$21:$C$30) -> 0.014573011 | E27: =D27*B27 -> 0.14573011
B28: =Summary!E29 -> 25 | C28: 200 | D28: =C28/SUM($C$21:$C$30) -> 0.0058292043 | E28: =D28*B28 -> 0.14573011
B29: =Summary!E30 -> 50 | C29: 100 | D29: =C29/SUM($C$21:$C$30) -> 0.0029146022 | E29: =D29*B29 -> 0.14573011
B30: =Summary!E31 -> 100 | C30: 10 | D30: =C30/SUM($C$21:$C$30) -> 0.00029146022 | E30: =D30*B30 -> 0.029146022
E31: =SUM(E21:E30) -> 1.4573011

Sheet ReelSet0
A1: [ "P3", "P4", "SCAT", "P6", "P3", "P3", "SCAT", "P2", "P4", "P5", "P5", "P4", "P5", "SCAT", "P6", "P6", "P5", "P3", "P5", "P4", "SCAT", "P6", "P3", "P6", "P3", "P4", "P5", "CP", "CP", "P2", "SCAT", "P6", "P5", "CP", "CP", "P6", "P3", "P4", "P3", "P3", "CP", "P4", "P2", "P5", "P6", "CP", "P5", "P6", "P2", "P4", "P3", "P6", "P4", "P5", "P2", "P4", "P1", "P6", "P6", "P4", "P2", "P2", "P1", "P4", "P1", "P5", "P1", "P1", "P5", "P1", "P4", "P6", "P3", "P2", "P1", "P5", "P6", "P2", "CP", "CP", "P5", "P4", "P1" ],
A2: [ "P6", "P5", "P4", "P3", "P4", "P6", "P6", "CP", "P5", "P3", "P4", "P6", "WILD", "P5", "P3", "P5", "CP", "P6", "P5", "P3", "WILD", "P4", "P5", "P2", "P5", "P3", "P4", "P4", "P5", "P1", "P3", "P5", "P2", "P4", "P6", "P6", "P4", "P2", "CP", "P5", "P2", "P6", "P2", "P3", "P5", "P1", "P3", "P1", "CP", "P6", "CP", "P3", "P4", "P6", "P2", "P3", "P2", "P3", "P6", "P4", "P3", "P2", "P1", "P5", "P2", "P4", "P2", "P5", "P1", "P4", "P4", "P1", "CP", "CP", "P6", "P4", "P6", "CP", "P4" ],
A3: [ "P5", "P3", "CP", "CP", "P6", "CP", "P6", "P3", "WILD", "P5", "P4", "P6", "P6", "P2", "P5", "P1", "SCAT", "P6", "P5", "P5", "P6", "P4", "SCAT", "P3", "P5", "P2", "P6", "SCAT", "CP", "CP", "P2", "WILD", "P4", "P6", "P5", "P1", "P4", "P5", "P6", "P6", "CP", "CP", "P3", "P2", "P5", "SCAT", "P3", "P6", "P2", "WILD", "P3", "P2", "P6", "P6", "P4", "CP", "P2", "P5", "P1", "SCAT", "P3", "P4", "P6", "P1", "CP", "CP", "P4", "P6", "P4", "P1", "P6", "P5", "P2", "P4", "P4", "P5", "P1", "P3", "P4", "CP", "CP", "P5", "P1", "P3", "P4", "P3" ],
A4: [ "P6", "P5", "P4", "WILD", "P3", "P3", "P6", "P2", "CP", "CP", "P5", "P6", "P6", "P3", "P4", "P6", "P5", "P3", "P5","P2", "P5", "P3", "P4", "P5", "P6", "P5", "P1", "WILD", "P4", "P4", "P5", "P3", "P1", "P5", "P6", "P4", "P4", "P6", "CP", "P5", "P2", "P2", "P3", "P5", "P3", "P3", "P1", "CP", "CP", "P3", "P4", "P6", "P2", "P3", "P2", "P3", "P6", "P4", "P3", "P2", "P1", "P5", "P2", "P4", "P2", "P5", "P1", "P4", "P4", "P1", "P6", "P4", "P6", "CP", "CP", "P4" ],
A5: [ "P6", "P6", "P5", "P3", "WILD", "P6", "P1", "P6", "P5", "P4", "P2", "P5", "WILD", "P6", "P1", "P5", "P5", "P6", "P4", "P3", "P5", "P2", "SCAT", "CP", "CP", "P6", "P6", "P2", "P4", "P5", "P1", "P4", "P5", "CP", "WILD", "P6", "CP", "P3", "P2", "P5", "P3", "SCAT", "P2", "P3", "P2", "WILD", "P4", "P2", "SCAT", "P5", "P1", "P3", "P4", "P6", "P1", "CP", "CP", "P4", "P6", "P4", "P1", "P6", "P5", "P2", "P4", "P4", "P5", "P1", "P3", "P4", "CP", "CP", "P5", "P1", "P3", "P4", "P3" ]
A7: =SUBSTITUTE(SUBSTITUTE(SUBSTITUTE(SUBSTITUTE(SUBSTITUTE(A1, " ",""), """", ""), "[", ""), "],",""), "]","") -> P3,P4,SCAT,P6,P3,P3,SCAT,P2,P4,P5,P5,P4,P5,SCAT,P6,P6,P5,P3,P5,P4,SCAT,P6,P3,P6,P3,P4,P5,CP,CP,P2,SCAT,P6,P5,CP,CP,P6,P3,P4,P3,P3,CP,P4,P2,P5,P6,CP,P5,P6,P2,P4,P3,P6,P4,P5,P2,P4,P1,P6,P6,P4,P2,P2,P1,P4,P1,P5,P1,P1,P5,P1,P4,P6,P3,P2,P1,P5,P6,P2,CP,CP,P5,P4,P1
A8: =SUBSTITUTE(SUBSTITUTE(SUBSTITUTE(SUBSTITUTE(SUBSTITUTE(A2, " ",""), """", ""), "[", ""), "],",""), "]","") -> P6,P5,P4,P3,P4,P6,P6,CP,P5,P3,P4,P6,WILD,P5,P3,P5,CP,P6,P5,P3,WILD,P4,P5,P2,P5,P3,P4,P4,P5,P1,P3,P5,P2,P4,P6,P6,P4,P2,CP,P5,P2,P6,P2,P3,P5,P1,P3,P1,CP,P6,CP,P3,P4,P6,P2,P3,P2,P3,P6,P4,P3,P2,P1,P5,P2,P4,P2,P5,P1,P4,P4,P1,CP,CP,P6,P4,P6,CP,P4
A9: =SUBSTITUTE(SUBSTITUTE(SUBSTITUTE(SUBSTITUTE(SUBSTITUTE(A3, " ",""), """", ""), "[", ""), "],",""), "]","") -> P5,P3,CP,CP,P6,CP,P6,P3,WILD,P5,P4,P6,P6,P2,P5,P1,SCAT,P6,P5,P5,P6,P4,SCAT,P3,P5,P2,P6,SCAT,CP,CP,P2,WILD,P4,P6,P5,P1,P4,P5,P6,P6,CP,CP,P3,P2,P5,SCAT,P3,P6,P2,WILD,P3,P2,P6,P6,P4,CP,P2,P5,P1,SCAT,P3,P4,P6,P1,CP,CP,P4,P6,P4,P1,P6,P5,P2,P4,P4,P5,P1,P3,P4,CP,CP,P5,P1,P3,P4,P3
A10: =SUBSTITUTE(SUBSTITUTE(SUBSTITUTE(SUBSTITUTE(SUBSTITUTE(A4, " ",""), """", ""), "[", ""), "],",""), "]","") -> P6,P5,P4,WILD,P3,P3,P6,P2,CP,CP,P5,P6,P6,P3,P4,P6,P5,P3,P5,P2,P5,P3,P4,P5,P6,P5,P1,WILD,P4,P4,P5,P3,P1,P5,P6,P4,P4,P6,CP,P5,P2,P2,P3,P5,P3,P3,P1,CP,CP,P3,P4,P6,P2,P3,P2,P3,P6,P4,P3,P2,P1,P5,P2,P4,P2,P5,P1,P4,P4,P1,P6,P4,P6,CP,CP,P4
A11: =SUBSTITUTE(SUBSTITUTE(SUBSTITUTE(SUBSTITUTE(SUBSTITUTE(A5, " ",""), """", ""), "[", ""), "],",""), "]","") -> P6,P6,P5,P3,WILD,P6,P1,P6,P5,P4,P2,P5,WILD,P6,P1,P5,P5,P6,P4,P3,P5,P2,SCAT,CP,CP,P6,P6,P2,P4,P5,P1,P4,P5,CP,WILD,P6,CP,P3,P2,P5,P3,SCAT,P2,P3,P2,WILD,P4,P2,SCAT,P5,P1,P3,P4,P6,P1,CP,CP,P4,P6,P4,P1,P6,P5,P2,P4,P4,P5,P1,P3,P4,CP,CP,P5,P1,P3,P4,P3
H13: cyclic reelset
G14: count | H14: =ROWS(TRANSPOSE(_xlfn.TEXTSPLIT(A7, ","))) -> 83 | I14: =ROWS(TRANSPOSE(_xlfn.TEXTSPLIT(A8, ","))) -> 79 | J14: =ROWS(TRANSPOSE(_xlfn.TEXTSPLIT(A9, ","))) -> 86 | K14: =ROWS(TRANSPOSE(_xlfn.TEXTSPLIT(A10, ","))) -> 76 | L14: =ROWS(TRANSPOSE(_xlfn.TEXTSPLIT(A11, ","))) -> 77
G15: start row | H15: =ROW(A18) -> 18 | I15: =ROW(B18) -> 18 | J15: =ROW(C18) -> 18 | K15: =ROW(D18) -> 18 | L15: =ROW(E18) -> 18 | N15: number of CashPrize per position
G16: height | H16: 3 | I16: 3 | J16: 3 | K16: 3 | L16: 3
A17: Reel 1 | B17: Reel 2 | C17: Reel 3 | D17: Reel 4 | E17: Reel 5 | H17: =A17 -> Reel 1 | I17: =B17 -> Reel 2 | J17: =C17 -> Reel 3 | K17: =D17 -> Reel 4 | L17: =E17 -> Reel 5 | N17: =H17 -> Reel 1 | O17: =I17 -> Reel 2 | P17: =J17 -> Reel 3 | Q17: =K17 -> Reel 4 | R17: =L17 -> Reel 5 | T17: Symbol | U17: Reel 1 | V17: Reel 2 | W17: Reel 3 | X17: Reel 4 | Y17: Reel 5 | AB17: Symbol | AC17: Occurs | AD17: Reel 1 | AE17: Reel 2 | AF17: Reel 3 | AG17: Reel 4 | AH17: Reel 5 | AI17: Hits | AJ17: Probability | AK17: 1 in | AL17: Awards | AM17: RTP % | AN17: Simulated | AO17: Diff | AR17: Line pays matrix
A18: {=TRANSPOSE(_xlfn.TEXTSPLIT(A7, ","))} -> P3 | B18: {=TRANSPOSE(_xlfn.TEXTSPLIT(A8, ","))} -> P6 | C18: {=TRANSPOSE(_xlfn.TEXTSPLIT(A9, ","))} -> P5 | D18: {=TRANSPOSE(_xlfn.TEXTSPLIT(A10, ","))} -> P6 | E18: {=TRANSPOSE(_xlfn.TEXTSPLIT(A11, ","))} -> P6 | H18: {=IF(ROW(A18)-H$15 < H$14,A18,IF(ROW(A18) - H$15 -H$16 + 1 < H$14,INDIRECT(ADDRESS(MOD(ROW(A18) - H$15, H$14) + H$15, COLUMN(A18))),""))} -> P3 | I18: {=IF(ROW(B18)-I$15 < I$14,B18,IF(ROW(B18) - I$15 -I$16 + 1 < I$14,INDIRECT(ADDRESS(MOD(ROW(B18) - I$15, I$14) + I$15, COLUMN(B18))),""))} -> P6 | J18: {=IF(ROW(C18)-J$15 < J$14,C18,IF(ROW(C18) - J$15 -J$16 + 1 < J$14,INDIRECT(ADDRESS(MOD(ROW(C18) - J$15, J$14) + J$15, COLUMN(C18))),""))} -> P5 | K18: {=IF(ROW(D18)-K$15 < K$14,D18,IF(ROW(D18) - K$15 -K$16 + 1 < K$14,INDIRECT(ADDRESS(MOD(ROW(D18) - K$15, K$14) + K$15, COLUMN(D18))),""))} -> P6 | L18: {=IF(ROW(E18)-L$15 < L$14,E18,IF(ROW(E18) - L$15 -L$16 + 1 < L$14,INDIRECT(ADDRESS(MOD(ROW(E18) - L$15, L$14) + L$15, COLUMN(E18))),""))} -> P6 | N18: {=IF(H18<>"", SUMPRODUCT((OFFSET(H18,0,0,H$16,1)=$T$24) +0),"")} -> 0 | O18: {=IF(I18<>"", SUMPRODUCT((OFFSET(I18,0,0,I$16,1)=$T$24) +0),"")} -> 0 | P18: {=IF(J18<>"", SUMPRODUCT((OFFSET(J18,0,0,J$16,1)=$T$24) +0),"")} -> 1 | Q18: {=IF(K18<>"", SUMPRODUCT((OFFSET(K18,0,0,K$16,1)=$T$24) +0),"")} -> 0 | R18: {=IF(L18<>"", SUMPRODUCT((OFFSET(L18,0,0,L$16,1)=$T$24) +0),"")} -> 0 | T18: =Summary!B4 -> P1 | U18: =COUNTIF(A$18:A$254,$T18) -> 8 | V18: =COUNTIF(B$18:B$254,$T18) -> 6 | W18: =COUNTIF(C$18:C$254,$T18) -> 7 | X18: =COUNTIF(D$18:D$254,$T18) -> 6 | Y18: =COUNTIF(E$18:E$254,$T18) -> 8 | AB18: =T18 -> P1 | AC18: 5 | AD18: =IF(_xlfn.XLOOKUP($AC18,$AR$18:$AR$22,AS$18:AS$22)=1, _xlfn.XLOOKUP($AB18,$T$18:$T$26,U$18:U$26)+U$25, IF(_xlfn.XLOOKUP($AC18,$AR$18:$AR$22,AS$18:AS$22)=0, U$27-(_xlfn.XLOOKUP($AB18,$T$18:$T$26,U$18:U$26)+U$25), U$27)) -> 8 | AE18: =IF(_xlfn.XLOOKUP($AC18,$AR$18:$AR$22,AT$18:AT$22)=1, _xlfn.XLOOKUP($AB18,$T$18:$T$26,V$18:V$26)+V$25, IF(_xlfn.XLOOKUP($AC18,$AR$18:$AR$22,AT$18:AT$22)=0, V$27-(_xlfn.XLOOKUP($AB18,$T$18:$T$26,V$18:V$26)+V$25), V$27)) -> 8 | AF18: =IF(_xlfn.XLOOKUP($AC18,$AR$18:$AR$22,AU$18:AU$22)=1, _xlfn.XLOOKUP($AB18,$T$18:$T$26,W$18:W$26)+W$25, IF(_xlfn.XLOOKUP($AC18,$AR$18:$AR$22,AU$18:AU$22)=0, W$27-(_xlfn.XLOOKUP($AB18,$T$18:$T$26,W$18:W$26)+W$25), W$27)) -> 10 | AG18: =IF(_xlfn.XLOOKUP($AC18,$AR$18:$AR$22,AV$18:AV$22)=1, _xlfn.XLOOKUP($AB18,$T$18:$T$26,X$18:X$26)+X$25, IF(_xlfn.XLOOKUP($AC18,$AR$18:$AR$22,AV$18:AV$22)=0, X$27-(_xlfn.XLOOKUP($AB18,$T$18:$T$26,X$18:X$26)+X$25), X$27)) -> 8 | AH18: =IF(_xlfn.XLOOKUP($AC18,$AR$18:$AR$22,AW$18:AW$22)=1, _xlfn.XLOOKUP($AB18,$T$18:$T$26,Y$18:Y$26)+Y$25, IF(_xlfn.XLOOKUP($AC18,$AR$18:$AR$22,AW$18:AW$22)=0, Y$27-(_xlfn.XLOOKUP($AB18,$T$18:$T$26,Y$18:Y$26)+Y$25), Y$27)) -> 12 | AI18: =PRODUCT(AD18:AH18) -> 61440 | AJ18: =AI18/$U$28 -> 1.8618439e-05 | AK18: =1/AJ18 -> 53710.197 | AL18: =IFERROR(INDEX(Summary!$C$4:$E$9, MATCH($AB18, Summary!$B$4:$B$9, 0), MATCH($AC18, Summary!$C$3:$E$3, 0)), 0) -> 1000 | AM18: =SUM(AJ18*AL18,AJ19*AL19,AJ20*AL20) -> 0.089562447 | AN18: 0.044904242 | AO18: =AM18-AN18 -> 0.044658205 | AR18: 5 | AS18: 1 | AT18: 1 | AU18: 1 | AV18: 1 | AW18: 1
A19: P4 | B19: P5 | C19: P3 | D19: P5 | E19: P6 | H19: {=IF(ROW(A19)-H$15 < H$14,A19,IF(ROW(A19) - H$15 -H$16 + 1 < H$14,INDIRECT(ADDRESS(MOD(ROW(A19) - H$15, H$14) + H$15, COLUMN(A19))),""))} -> P4 | I19: {=IF(ROW(B19)-I$15 < I$14,B19,IF(ROW(B19) - I$15 -I$16 + 1 < I$14,INDIRECT(ADDRESS(MOD(ROW(B19) - I$15, I$14) + I$15, COLUMN(B19))),""))} -> P5 | J19: {=IF(ROW(C19)-J$15 < J$14,C19,IF(ROW(C19) - J$15 -J$16 + 1 < J$14,INDIRECT(ADDRESS(MOD(ROW(C19) - J$15, J$14) + J$15, COLUMN(C19))),""))} -> P3 | K19: {=IF(ROW(D19)-K$15 < K$14,D19,IF(ROW(D19) - K$15 -K$16 + 1 < K$14,INDIRECT(ADDRESS(MOD(ROW(D19) - K$15, K$14) + K$15, COLUMN(D19))),""))} -> P5 | L19: {=IF(ROW(E19)-L$15 < L$14,E19,IF(ROW(E19) - L$15 -L$16 + 1 < L$14,INDIRECT(ADDRESS(MOD(ROW(E19) - L$15, L$14) + L$15, COLUMN(E19))),""))} -> P6 | N19: {=IF(H19<>"", SUMPRODUCT((OFFSET(H19,0,0,H$16,1)=$T$24) +0),"")} -> 0 | O19: {=IF(I19<>"", SUMPRODUCT((OFFSET(I19,0,0,I$16,1)=$T$24) +0),"")} -> 0 | P19: {=IF(J19<>"", SUMPRODUCT((OFFSET(J19,0,0,J$16,1)=$T$24) +0),"")} -> 2 | Q19: {=IF(K19<>"", SUMPRODUCT((OFFSET(K19,0,0,K$16,1)=$T$24) +0),"")} -> 0 | R19: {=IF(L19<>"", SUMPRODUCT((OFFSET(L19,0,0,L$16,1)=$T$24) +0),"")} -> 0 | T19: =Summary!B5 -> P2 | U19: =COUNTIF(A$18:A$254,$T19) -> 9 | V19: =COUNTIF(B$18:B$254,$T19) -> 10 | W19: =COUNTIF(C$18:C$254,$T19) -> 8 | X19: =COUNTIF(D$18:D$254,$T19) -> 9 | Y19: =COUNTIF(E$18:E$254,$T19) -> 8 | AB19: =T18 -> P1 | AC19: 4 | AD19: =IF(_xlfn.XLOOKUP($AC19,$AR$18:$AR$22,AS$18:AS$22)=1, _xlfn.XLOOKUP($AB19,$T$18:$T$26,U$18:U$26)+U$25, IF(_xlfn.XLOOKUP($AC19,$AR$18:$AR$22,AS$18:AS$22)=0, U$27-(_xlfn.XLOOKUP($AB19,$T$18:$T$26,U$18:U$26)+U$25), U$27)) -> 8 | AE19: =IF(_xlfn.XLOOKUP($AC19,$AR$18:$AR$22,AT$18:AT$22)=1, _xlfn.XLOOKUP($AB19,$T$18:$T$26,V$18:V$26)+V$25, IF(_xlfn.XLOOKUP($AC19,$AR$18:$AR$22,AT$18:AT$22)=0, V$27-(_xlfn.XLOOKUP($AB19,$T$18:$T$26,V$18:V$26)+V$25), V$27)) -> 8 | AF19: =IF(_xlfn.XLOOKUP($AC19,$AR$18:$AR$22,AU$18:AU$22)=1, _xlfn.XLOOKUP($AB19,$T$18:$T$26,W$18:W$26)+W$25, IF(_xlfn.XLOOKUP($AC19,$AR$18:$AR$22,AU$18:AU$22)=0, W$27-(_xlfn.XLOOKUP($AB19,$T$18:$T$26,W$18:W$26)+W$25), W$27)) -> 10 | AG19: =IF(_xlfn.XLOOKUP($AC19,$AR$18:$AR$22,AV$18:AV$22)=1, _xlfn.XLOOKUP($AB19,$T$18:$T$26,X$18:X$26)+X$25, IF(_xlfn.XLOOKUP($AC19,$AR$18:$AR$22,AV$18:AV$22)=0, X$27-(_xlfn.XLOOKUP($AB19,$T$18:$T$26,X$18:X$26)+X$25), X$27)) -> 8 | AH19: =IF(_xlfn.XLOOKUP($AC19,$AR$18:$AR$22,AW$18:AW$22)=1, _xlfn.XLOOKUP($AB19,$T$18:$T$26,Y$18:Y$26)+Y$25, IF(_xlfn.XLOOKUP($AC19,$AR$18:$AR$22,AW$18:AW$22)=0, Y$27-(_xlfn.XLOOKUP($AB19,$T$18:$T$26,Y$18:Y$26)+Y$25), Y$27)) -> 65 | AI19: =PRODUCT(AD19:AH19) -> 332800 | AJ19: =AI19/$U$28 -> 0.00010084988 | AK19: =1/AJ19 -> 9915.7287 | AL19: =IFERROR(INDEX(Summary!$C$4:$E$9, MATCH($AB19, Summary!$B$4:$B$9, 0), MATCH($AC19, Summary!$C$3:$E$3, 0)), 0) -> 200 | AR19: 4 | AS19: 1 | AT19: 1 | AU19: 1 | AV19: 1 | AW19: 0
A20: SCAT | B20: P4 | C20: CP | D20: P4 | E20: P5 | H20: {=IF(ROW(A20)-H$15 < H$14,A20,IF(ROW(A20) - H$15 -H$16 + 1 < H$14,INDIRECT(ADDRESS(MOD(ROW(A20) - H$15, H$14) + H$15, COLUMN(A20))),""))} -> SCAT | I20: {=IF(ROW(B20)-I$15 < I$14,B20,IF(ROW(B20) - I$15 -I$16 + 1 < I$14,INDIRECT(ADDRESS(MOD(ROW(B20) - I$15, I$14) + I$15, COLUMN(B20))),""))} -> P4 | J20: {=IF(ROW(C20)-J$15 < J$14,C20,IF(ROW(C20) - J$15 -J$16 + 1 < J$14,INDIRECT(ADDRESS(MOD(ROW(C20) - J$15, J$14) + J$15, COLUMN(C20))),""))} -> CP | K20: {=IF(ROW(D20)-K$15 < K$14,D20,IF(ROW(D20) - K$15 -K$16 + 1 < K$14,INDIRECT(ADDRESS(MOD(ROW(D20) - K$15, K$14) + K$15, COLUMN(D20))),""))} -> P4 | L20: {=IF(ROW(E20)-L$15 < L$14,E20,IF(ROW(E20) - L$15 -L$16 + 1 < L$14,INDIRECT(ADDRESS(MOD(ROW(E20) - L$15, L$14) + L$15, COLUMN(E20))),""))} -> P5 | N20: {=IF(H20<>"", SUMPRODUCT((OFFSET(H20,0,0,H$16,1)=$T$24) +0),"")} -> 0 | O20: {=IF(I20<>"", SUMPRODUCT((OFFSET(I20,0,0,I$16,1)=$T$24) +0),"")} -> 0 | P20: {=IF(J20<>"", SUMPRODUCT((OFFSET(J20,0,0,J$16,1)=$T$24) +0),"")} -> 2 | Q20: {=IF(K20<>"", SUMPRODUCT((OFFSET(K20,0,0,K$16,1)=$T$24) +0),"")} -> 0 | R20: {=IF(L20<>"", SUMPRODUCT((OFFSET(L20,0,0,L$16,1)=$T$24) +0),"")} -> 0 | T20: =Summary!B6 -> P3 | U20: =COUNTIF(A$18:A$254,$T20) -> 11 | V20: =COUNTIF(B$18:B$254,$T20) -> 12 | W20: =COUNTIF(C$18:C$254,$T20) -> 10 | X20: =COUNTIF(D$18:D$254,$T20) -> 13 | Y20: =COUNTIF(E$18:E$254,$T20) -> 9 | AB20: =T18 -> P1 | AC20: 3 | AD20: =IF(_xlfn.XLOOKUP($AC20,$AR$18:$AR$22,AS$18:AS$22)=1, _xlfn.XLOOKUP($AB20,$T$18:$T$26,U$18:U$26)+U$25, IF(_xlfn.XLOOKUP($AC20,$AR$18:$AR$22,AS$18:AS$22)=0, U$27-(_xlfn.XLOOKUP($AB20,$T$18:$T$26,U$18:U$26)+U$25), U$27)) -> 8 | AE20: =IF(_xlfn.XLOOKUP($AC20,$AR$18:$AR$22,AT$18:AT$22)=1, _xlfn.XLOOKUP($AB20,$T$18:$T$26,V$18:V$26)+V$25, IF(_xlfn.XLOOKUP($AC20,$AR$18:$AR$22,AT$18:AT$22)=0, V$27-(_xlfn.XLOOKUP($AB20,$T$18:$T$26,V$18:V$26)+V$25), V$27)) -> 8 | AF20: =IF(_xlfn.XLOOKUP($AC20,$AR$18:$AR$22,AU$18:AU$22)=1, _xlfn.XLOOKUP($AB20,$T$18:$T$26,W$18:W$26)+W$25, IF(_xlfn.XLOOKUP($AC20,$AR$18:$AR$22,AU$18:AU$22)=0, W$27-(_xlfn.XLOOKUP($AB20,$T$18:$T$26,W$18:W$26)+W$25), W$27)) -> 10 | AG20: =IF(_xlfn.XLOOKUP($AC20,$AR$18:$AR$22,AV$18:AV$22)=1, _xlfn.XLOOKUP($AB20,$T$18:$T$26,X$18:X$26)+X$25, IF(_xlfn.XLOOKUP($AC20,$AR$18:$AR$22,AV$18:AV$22)=0, X$27-(_xlfn.XLOOKUP($AB20,$T$18:$T$26,X$18:X$26)+X$25), X$27)) -> 68 | AH20: =IF(_xlfn.XLOOKUP($AC20,$AR$18:$AR$22,AW$18:AW$22)=1, _xlfn.XLOOKUP($AB20,$T$18:$T$26,Y$18:Y$26)+Y$25, IF(_xlfn.XLOOKUP($AC20,$AR$18:$AR$22,AW$18:AW$22)=0, Y$27-(_xlfn.XLOOKUP($AB20,$T$18:$T$26,Y$18:Y$26)+Y$25), Y$27)) -> 77 | AI20: =PRODUCT(AD20:AH20) -> 3351040 | AJ20: =AI20/$U$28 -> 0.0010154807 | AK20: =1/AJ20 -> 984.75533 | AL20: =IFERROR(INDEX(Summary!$C$4:$E$9, MATCH($AB20, Summary!$B$4:$B$9, 0), MATCH($AC20, Summary!$C$3:$E$3, 0)), 0) -> 50 | AR20: 3 | AS20: 1 | AT20: 1 | AU20: 1 | AV20: 0 | AW20: -1
A21: P6 | B21: P3 | C21: CP | D21: WILD | E21: P3 | H21: {=IF(ROW(A21)-H$15 < H$14,A21,IF(ROW(A21) - H$15 -H$16 + 1 < H$14,INDIRECT(ADDRESS(MOD(ROW(A21) - H$15, H$14) + H$15, COLUMN(A21))),""))} -> P6 | I21: {=IF(ROW(B21)-I$15 < I$14,B21,IF(ROW(B21) - I$15 -I$16 + 1 < I$14,INDIRECT(ADDRESS(MOD(ROW(B21) - I$15, I$14) + I$15, COLUMN(B21))),""))} -> P3 | J21: {=IF(ROW(C21)-J$15 < J$14,C21,IF(ROW(C21) - J$15 -J$16 + 1 < J$14,INDIRECT(ADDRESS(MOD(ROW(C21) - J$15, J$14) + J$15, COLUMN(C21))),""))} -> CP | K21: {=IF(ROW(D21)-K$15 < K$14,D21,IF(ROW(D21) - K$15 -K$16 + 1 < K$14,INDIRECT(ADDRESS(MOD(ROW(D21) - K$15, K$14) + K$15, COLUMN(D21))),""))} -> WILD | L21: {=IF(ROW(E21)-L$15 < L$14,E21,IF(ROW(E21) - L$15 -L$16 + 1 < L$14,INDIRECT(ADDRESS(MOD(ROW(E21) - L$15, L$14) + L$15, COLUMN(E21))),""))} -> P3 | N21: {=IF(H21<>"", SUMPRODUCT((OFFSET(H21,0,0,H$16,1)=$T$24) +0),"")} -> 0 | O21: {=IF(I21<>"", SUMPRODUCT((OFFSET(I21,0,0,I$16,1)=$T$24) +0),"")} -> 0 | P21: {=IF(J21<>"", SUMPRODUCT((OFFSET(J21,0,0,J$16,1)=$T$24) +0),"")} -> 2 | Q21: {=IF(K21<>"", SUMPRODUCT((OFFSET(K21,0,0,K$16,1)=$T$24) +0),"")} -> 0 | R21: {=IF(L21<>"", SUMPRODUCT((OFFSET(L21,0,0,L$16,1)=$T$24) +0),"")} -> 0 | T21: =Summary!B7 -> P4 | U21: =COUNTIF(A$18:A$254,$T21) -> 14 | V21: =COUNTIF(B$18:B$254,$T21) -> 15 | W21: =COUNTIF(C$18:C$254,$T21) -> 12 | X21: =COUNTIF(D$18:D$254,$T21) -> 14 | Y21: =COUNTIF(E$18:E$254,$T21) -> 12 | AB21: =T19 -> P2 | AC21: 5 | AD21: =IF(_xlfn.XLOOKUP($AC21,$AR$18:$AR$22,AS$18:AS$22)=1, _xlfn.XLOOKUP($AB21,$T$18:$T$26,U$18:U$26)+U$25, IF(_xlfn.XLOOKUP($AC21,$AR$18:$AR$22,AS$18:AS$22)=0, U$27-(_xlfn.XLOOKUP($AB21,$T$18:$T$26,U$18:U$26)+U$25), U$27)) -> 9 | AE21: =IF(_xlfn.XLOOKUP($AC21,$AR$18:$AR$22,AT$18:AT$22)=1, _xlfn.XLOOKUP($AB21,$T$18:$T$26,V$18:V$26)+V$25, IF(_xlfn.XLOOKUP($AC21,$AR$18:$AR$22,AT$18:AT$22)=0, V$27-(_xlfn.XLOOKUP($AB21,$T$18:$T$26,V$18:V$26)+V$25), V$27)) -> 12 | AF21: =IF(_xlfn.XLOOKUP($AC21,$AR$18:$AR$22,AU$18:AU$22)=1, _xlfn.XLOOKUP($AB21,$T$18:$T$26,W$18:W$26)+W$25, IF(_xlfn.XLOOKUP($AC21,$AR$18:$AR$22,AU$18:AU$22)=0, W$27-(_xlfn.XLOOKUP($AB21,$T$18:$T$26,W$18:W$26)+W$25), W$27)) -> 11 | AG21: =IF(_xlfn.XLOOKUP($AC21,$AR$18:$AR$22,AV$18:AV$22)=1, _xlfn.XLOOKUP($AB21,$T$18:$T$26,X$18:X$26)+X$25, IF(_xlfn.XLOOKUP($AC21,$AR$18:$AR$22,AV$18:AV$22)=0, X$27-(_xlfn.XLOOKUP($AB21,$T$18:$T$26,X$18:X$26)+X$25), X$27)) -> 11 | AH21: =IF(_xlfn.XLOOKUP($AC21,$AR$18:$AR$22,AW$18:AW$22)=1, _xlfn.XLOOKUP($AB21,$T$18:$T$26,Y$18:Y$26)+Y$25, IF(_xlfn.XLOOKUP($AC21,$AR$18:$AR$22,AW$18:AW$22)=0, Y$27-(_xlfn.XLOOKUP($AB21,$T$18:$T$26,Y$18:Y$26)+Y$25), Y$27)) -> 12 | AI21: =PRODUCT(AD21:AH21) -> 156816 | AJ21: =AI21/$U$28 -> 4.7520655e-05 | AK21: =1/AJ21 -> 21043.481 | AL21: =IFERROR(INDEX(Summary!$C$4:$E$9, MATCH($AB21, Summary!$B$4:$B$9, 0), MATCH($AC21, Summary!$C$3:$E$3, 0)), 0) -> 500 | AM21: =SUM(AJ21*AL21,AJ22*AL22,AJ23*AL23) -> 0.085537179 | AN21: 0.092205119 | AO21: 1.0467552
A22: P3 | B22: P4 | C22: P6 | D22: P3 | E22: WILD | H22: {=IF(ROW(A22)-H$15 < H$14,A22,IF(ROW(A22) - H$15 -H$16 + 1 < H$14,INDIRECT(ADDRESS(MOD(ROW(A22) - H$15, H$14) + H$15, COLUMN(A22))),""))} -> P3 | I22: {=IF(ROW(B22)-I$15 < I$14,B22,IF(ROW(B22) - I$15 -I$16 + 1 < I$14,INDIRECT(ADDRESS(MOD(ROW(B22) - I$15, I$14) + I$15, COLUMN(B22))),""))} -> P4 | J22: {=IF(ROW(C22)-J$15 < J$14,C22,IF(ROW(C22) - J$15 -J$16 + 1 < J$14,INDIRECT(ADDRESS(MOD(ROW(C22) - J$15, J$14) + J$15, COLUMN(C22))),""))} -> P6 | K22: {=IF(ROW(D22)-K$15 < K$14,D22,IF(ROW(D22) - K$15 -K$16 + 1 < K$14,INDIRECT(ADDRESS(MOD(ROW(D22) - K$15, K$14) + K$15, COLUMN(D22))),""))} -> P3 | L22: {=IF(ROW(E22)-L$15 < L$14,E22,IF(ROW(E22) - L$15 -L$16 + 1 < L$14,INDIRECT(ADDRESS(MOD(ROW(E22) - L$15, L$14) + L$15, COLUMN(E22))),""))} -> WILD | N22: {=IF(H22<>"", SUMPRODUCT((OFFSET(H22,0,0,H$16,1)=$T$24) +0),"")} -> 0 | O22: {=IF(I22<>"", SUMPRODUCT((OFFSET(I22,0,0,I$16,1)=$T$24) +0),"")} -> 0 | P22: {=IF(J22<>"", SUMPRODUCT((OFFSET(J22,0,0,J$16,1)=$T$24) +0),"")} -> 1 | Q22: {=IF(K22<>"", SUMPRODUCT((OFFSET(K22,0,0,K$16,1)=$T$24) +0),"")} -> 0 | R22: {=IF(L22<>"", SUMPRODUCT((OFFSET(L22,0,0,L$16,1)=$T$24) +0),"")} -> 0 | T22: =Summary!B8 -> P5 | U22: =COUNTIF(A$18:A$254,$T22) -> 14 | V22: =COUNTIF(B$18:B$254,$T22) -> 13 | W22: =COUNTIF(C$18:C$254,$T22) -> 13 | X22: =COUNTIF(D$18:D$254,$T22) -> 13 | Y22: =COUNTIF(E$18:E$254,$T22) -> 13 | AB22: =T19 -> P2 | AC22: 4 | AD22: =IF(_xlfn.XLOOKUP($AC22,$AR$18:$AR$22,AS$18:AS$22)=1, _xlfn.XLOOKUP($AB22,$T$18:$T$26,U$18:U$26)+U$25, IF(_xlfn.XLOOKUP($AC22,$AR$18:$AR$22,AS$18:AS$22)=0, U$27-(_xlfn.XLOOKUP($AB22,$T$18:$T$26,U$18:U$26)+U$25), U$27)) -> 9 | AE22: =IF(_xlfn.XLOOKUP($AC22,$AR$18:$AR$22,AT$18:AT$22)=1, _xlfn.XLOOKUP($AB22,$T$18:$T$26,V$18:V$26)+V$25, IF(_xlfn.XLOOKUP($AC22,$AR$18:$AR$22,AT$18:AT$22)=0, V$27-(_xlfn.XLOOKUP($AB22,$T$18:$T$26,V$18:V$26)+V$25), V$27)) -> 12 | AF22: =IF(_xlfn.XLOOKUP($AC22,$AR$18:$AR$22,AU$18:AU$22)=1, _xlfn.XLOOKUP($AB22,$T$18:$T$26,W$18:W$26)+W$25, IF(_xlfn.XLOOKUP($AC22,$AR$18:$AR$22,AU$18:AU$22)=0, W$27-(_xlfn.XLOOKUP($AB22,$T$18:$T$26,W$18:W$26)+W$25), W$27)) -> 11 | AG22: =IF(_xlfn.XLOOKUP($AC22,$AR$18:$AR$22,AV$18:AV$22)=1, _xlfn.XLOOKUP($AB22,$T$18:$T$26,X$18:X$26)+X$25, IF(_xlfn.XLOOKUP($AC22,$AR$18:$AR$22,AV$18:AV$22)=0, X$27-(_xlfn.XLOOKUP($AB22,$T$18:$T$26,X$18:X$26)+X$25), X$27)) -> 11 | AH22: =IF(_xlfn.XLOOKUP($AC22,$AR$18:$AR$22,AW$18:AW$22)=1, _xlfn.XLOOKUP($AB22,$T$18:$T$26,Y$18:Y$26)+Y$25, IF(_xlfn.XLOOKUP($AC22,$AR$18:$AR$22,AW$18:AW$22)=0, Y$27-(_xlfn.XLOOKUP($AB22,$T$18:$T$26,Y$18:Y$26)+Y$25), Y$27)) -> 65 | AI22: =PRODUCT(AD22:AH22) -> 849420 | AJ22: =AI22/$U$28 -> 0.00025740355 | AK22: =1/AJ22 -> 3884.9503 | AL22: =IFERROR(INDEX(Summary!$C$4:$E$9, MATCH($AB22, Summary!$B$4:$B$9, 0), MATCH($AC22, Summary!$C$3:$E$3, 0)), 0) -> 100
A23: P3 | B23: P6 | C23: CP | D23: P3 | E23: P6 | H23: {=IF(ROW(A23)-H$15 < H$14,A23,IF(ROW(A23) - H$15 -H$16 + 1 < H$14,INDIRECT(ADDRESS(MOD(ROW(A23) - H$15, H$14) + H$15, COLUMN(A23))),""))} -> P3 | I23: {=IF(ROW(B23)-I$15 < I$14,B23,IF(ROW(B23) - I$15 -I$16 + 1 < I$14,INDIRECT(ADDRESS(MOD(ROW(B23) - I$15, I$14) + I$15, COLUMN(B23))),""))} -> P6 | J23: {=IF(ROW(C23)-J$15 < J$14,C23,IF(ROW(C23) - J$15 -J$16 + 1 < J$14,INDIRECT(ADDRESS(MOD(ROW(C23) - J$15, J$14) + J$15, COLUMN(C23))),""))} -> CP | K23: {=IF(ROW(D23)-K$15 < K$14,D23,IF(ROW(D23) - K$15 -K$16 + 1 < K$14,INDIRECT(ADDRESS(MOD(ROW(D23) - K$15, K$14) + K$15, COLUMN(D23))),""))} -> P3 | L23: {=IF(ROW(E23)-L$15 < L$14,E23,IF(ROW(E23) - L$15 -L$16 + 1 < L$14,INDIRECT(ADDRESS(MOD(ROW(E23) - L$15, L$14) + L$15, COLUMN(E23))),""))} -> P6 | N23: {=IF(H23<>"", SUMPRODUCT((OFFSET(H23,0,0,H$16,1)=$T$24) +0),"")} -> 0 | O23: {=IF(I23<>"", SUMPRODUCT((OFFSET(I23,0,0,I$16,1)=$T$24) +0),"")} -> 1 | P23: {=IF(J23<>"", SUMPRODUCT((OFFSET(J23,0,0,J$16,1)=$T$24) +0),"")} -> 1 | Q23: {=IF(K23<>"", SUMPRODUCT((OFFSET(K23,0,0,K$16,1)=$T$24) +0),"")} -> 0 | R23: {=IF(L23<>"", SUMPRODUCT((OFFSET(L23,0,0,L$16,1)=$T$24) +0),"")} -> 0 | T23: =Summary!B9 -> P6 | U23: =COUNTIF(A$18:A$254,$T23) -> 14 | V23: =COUNTIF(B$18:B$254,$T23) -> 13 | W23: =COUNTIF(C$18:C$254,$T23) -> 16 | X23: =COUNTIF(D$18:D$254,$T23) -> 12 | Y23: =COUNTIF(E$18:E$254,$T23) -> 12 | AB23: =T19 -> P2 | AC23: 3 | AD23: =IF(_xlfn.XLOOKUP($AC23,$AR$18:$AR$22,AS$18:AS$22)=1, _xlfn.XLOOKUP($AB23,$T$18:$T$26,U$18:U$26)+U$25, IF(_xlfn.XLOOKUP($AC23,$AR$18:$AR$22,AS$18:AS$22)=0, U$27-(_xlfn.XLOOKUP($AB23,$T$18:$T$26,U$18:U$26)+U$25), U$27)) -> 9 | AE23: =IF(_xlfn.XLOOKUP($AC23,$AR$18:$AR$22,AT$18:AT$22)=1, _xlfn.XLOOKUP($AB23,$T$18:$T$26,V$18:V$26)+V$25, IF(_xlfn.XLOOKUP($AC23,$AR$18:$AR$22,AT$18:AT$22)=0, V$27-(_xlfn.XLOOKUP($AB23,$T$18:$T$26,V$18:V$26)+V$25), V$27)) -> 12 | AF23: =IF(_xlfn.XLOOKUP($AC23,$AR$18:$AR$22,AU$18:AU$22)=1, _xlfn.XLOOKUP($AB23,$T$18:$T$26,W$18:W$26)+W$25, IF(_xlfn.XLOOKUP($AC23,$AR$18:$AR$22,AU$18:AU$22)=0, W$27-(_xlfn.XLOOKUP($AB23,$T$18:$T$26,W$18:W$26)+W$25), W$27)) -> 11 | AG23: =IF(_xlfn.XLOOKUP($AC23,$AR$18:$AR$22,AV$18:AV$22)=1, _xlfn.XLOOKUP($AB23,$T$18:$T$26,X$18:X$26)+X$25, IF(_xlfn.XLOOKUP($AC23,$AR$18:$AR$22,AV$18:AV$22)=0, X$27-(_xlfn.XLOOKUP($AB23,$T$18:$T$26,X$18:X$26)+X$25), X$27)) -> 65 | AH23: =IF(_xlfn.XLOOKUP($AC23,$AR$18:$AR$22,AW$18:AW$22)=1, _xlfn.XLOOKUP($AB23,$T$18:$T$26,Y$18:Y$26)+Y$25, IF(_xlfn.XLOOKUP($AC23,$AR$18:$AR$22,AW$18:AW$22)=0, Y$27-(_xlfn.XLOOKUP($AB23,$T$18:$T$26,Y$18:Y$26)+Y$25), Y$27)) -> 77 | AI23: =PRODUCT(AD23:AH23) -> 5945940 | AJ23: =AI23/$U$28 -> 0.0018018248 | AK23: =1/AJ23 -> 554.9929 | AL23: =IFERROR(INDEX(Summary!$C$4:$E$9, MATCH($AB23, Summary!$B$4:$B$9, 0), MATCH($AC23, Summary!$C$3:$E$3, 0)), 0) -> 20
A24: SCAT | B24: P6 | C24: P6 | D24: P6 | E24: P1 | H24: {=IF(ROW(A24)-H$15 < H$14,A24,IF(ROW(A24) - H$15 -H$16 + 1 < H$14,INDIRECT(ADDRESS(MOD(ROW(A24) - H$15, H$14) + H$15, COLUMN(A24))),""))} -> SCAT | I24: {=IF(ROW(B24)-I$15 < I$14,B24,IF(ROW(B24) - I$15 -I$16 + 1 < I$14,INDIRECT(ADDRESS(MOD(ROW(B24) - I$15, I$14) + I$15, COLUMN(B24))),""))} -> P6 | J24: {=IF(ROW(C24)-J$15 < J$14,C24,IF(ROW(C24) - J$15 -J$16 + 1 < J$14,INDIRECT(ADDRESS(MOD(ROW(C24) - J$15, J$14) + J$15, COLUMN(C24))),""))} -> P6 | K24: {=IF(ROW(D24)-K$15 < K$14,D24,IF(ROW(D24) - K$15 -K$16 + 1 < K$14,INDIRECT(ADDRESS(MOD(ROW(D24) - K$15, K$14) + K$15, COLUMN(D24))),""))} -> P6 | L24: {=IF(ROW(E24)-L$15 < L$14,E24,IF(ROW(E24) - L$15 -L$16 + 1 < L$14,INDIRECT(ADDRESS(MOD(ROW(E24) - L$15, L$14) + L$15, COLUMN(E24))),""))} -> P1 | N24: {=IF(H24<>"", SUMPRODUCT((OFFSET(H24,0,0,H$16,1)=$T$24) +0),"")} -> 0 | O24: {=IF(I24<>"", SUMPRODUCT((OFFSET(I24,0,0,I$16,1)=$T$24) +0),"")} -> 1 | P24: {=IF(J24<>"", SUMPRODUCT((OFFSET(J24,0,0,J$16,1)=$T$24) +0),"")} -> 0 | Q24: {=IF(K24<>"", SUMPRODUCT((OFFSET(K24,0,0,K$16,1)=$T$24) +0),"")} -> 1 | R24: {=IF(L24<>"", SUMPRODUCT((OFFSET(L24,0,0,L$16,1)=$T$24) +0),"")} -> 0 | T24: =Summary!B10 -> CP | U24: =COUNTIF(A$18:A$254,$T24) -> 8 | V24: =COUNTIF(B$18:B$254,$T24) -> 8 | W24: =COUNTIF(C$18:C$254,$T24) -> 12 | X24: =COUNTIF(D$18:D$254,$T24) -> 7 | Y24: =COUNTIF(E$18:E$254,$T24) -> 8 | AB24: =T20 -> P3 | AC24: 5 | AD24: =IF(_xlfn.XLOOKUP($AC24,$AR$18:$AR$22,AS$18:AS$22)=1, _xlfn.XLOOKUP($AB24,$T$18:$T$26,U$18:U$26)+U$25, IF(_xlfn.XLOOKUP($AC24,$AR$18:$AR$22,AS$18:AS$22)=0, U$27-(_xlfn.XLOOKUP($AB24,$T$18:$T$26,U$18:U$26)+U$25), U$27)) -> 11 | AE24: =IF(_xlfn.XLOOKUP($AC24,$AR$18:$AR$22,AT$18:AT$22)=1, _xlfn.XLOOKUP($AB24,$T$18:$T$26,V$18:V$26)+V$25, IF(_xlfn.XLOOKUP($AC24,$AR$18:$AR$22,AT$18:AT$22)=0, V$27-(_xlfn.XLOOKUP($AB24,$T$18:$T$26,V$18:V$26)+V$25), V$27)) -> 14 | AF24: =IF(_xlfn.XLOOKUP($AC24,$AR$18:$AR$22,AU$18:AU$22)=1, _xlfn.XLOOKUP($AB24,$T$18:$T$26,W$18:W$26)+W$25, IF(_xlfn.XLOOKUP($AC24,$AR$18:$AR$22,AU$18:AU$22)=0, W$27-(_xlfn.XLOOKUP($AB24,$T$18:$T$26,W$18:W$26)+W$25), W$27)) -> 13 | AG24: =IF(_xlfn.XLOOKUP($AC24,$AR$18:$AR$22,AV$18:AV$22)=1, _xlfn.XLOOKUP($AB24,$T$18:$T$26,X$18:X$26)+X$25, IF(_xlfn.XLOOKUP($AC24,$AR$18:$AR$22,AV$18:AV$22)=0, X$27-(_xlfn.XLOOKUP($AB24,$T$18:$T$26,X$18:X$26)+X$25), X$27)) -> 15 | AH24: =IF(_xlfn.XLOOKUP($AC24,$AR$18:$AR$22,AW$18:AW$22)=1, _xlfn.XLOOKUP($AB24,$T$18:$T$26,Y$18:Y$26)+Y$25, IF(_xlfn.XLOOKUP($AC24,$AR$18:$AR$22,AW$18:AW$22)=0, Y$27-(_xlfn.XLOOKUP($AB24,$T$18:$T$26,Y$18:Y$26)+Y$25), Y$27)) -> 13 | AI24: =PRODUCT(AD24:AH24) -> 390390 | AJ24: =AI24/$U$28 -> 0.00011830163 | AK24: =1/AJ24 -> 8452.9688 | AL24: =IFERROR(INDEX(Summary!$C$4:$E$9, MATCH($AB24, Summary!$B$4:$B$9, 0), MATCH($AC24, Summary!$C$3:$E$3, 0)), 0) -> 250 | AM24: =SUM(AJ24*AL24,AJ25*AL25,AJ26*AL26) -> 0.087191335 | AN24: 0.0236712 | AO24: 1.0236712
A25: P2 | B25: CP | C25: P3 | D25: P2 | E25: P6 | H25: {=IF(ROW(A25)-H$15 < H$14,A25,IF(ROW(A25) - H$15 -H$16 + 1 < H$14,INDIRECT(ADDRESS(MOD(ROW(A25) - H$15, H$14) + H$15, COLUMN(A25))),""))} -> P2 | I25: {=IF(ROW(B25)-I$15 < I$14,B25,IF(ROW(B25) - I$15 -I$16 + 1 < I$14,INDIRECT(ADDRESS(MOD(ROW(B25) - I$15, I$14) + I$15, COLUMN(B25))),""))} -> CP | J25: {=IF(ROW(C25)-J$15 < J$14,C25,IF(ROW(C25) - J$15 -J$16 + 1 < J$14,INDIRECT(ADDRESS(MOD(ROW(C25) - J$15, J$14) + J$15, COLUMN(C25))),""))} -> P3 | K25: {=IF(ROW(D25)-K$15 < K$14,D25,IF(ROW(D25) - K$15 -K$16 + 1 < K$14,INDIRECT(ADDRESS(MOD(ROW(D25) - K$15, K$14) + K$15, COLUMN(D25))),""))} -> P2 | L25: {=IF(ROW(E25)-L$15 < L$14,E25,IF(ROW(E25) - L$15 -L$16 + 1 < L$14,INDIRECT(ADDRESS(MOD(ROW(E25) - L$15, L$14) + L$15, COLUMN(E25))),""))} -> P6 | N25: {=IF(H25<>"", SUMPRODUCT((OFFSET(H25,0,0,H$16,1)=$T$24) +0),"")} -> 0 | O25: {=IF(I25<>"", SUMPRODUCT((OFFSET(I25,0,0,I$16,1)=$T$24) +0),"")} -> 1 | P25: {=IF(J25<>"", SUMPRODUCT((OFFSET(J25,0,0,J$16,1)=$T$24) +0),"")} -> 0 | Q25: {=IF(K25<>"", SUMPRODUCT((OFFSET(K25,0,0,K$16,1)=$T$24) +0),"")} -> 2 | R25: {=IF(L25<>"", SUMPRODUCT((OFFSET(L25,0,0,L$16,1)=$T$24) +0),"")} -> 0 | T25: =Summary!B11 -> WILD | U25: =COUNTIF(A$18:A$254,$T25) -> 0 | V25: =COUNTIF(B$18:B$254,$T25) -> 2 | W25: =COUNTIF(C$18:C$254,$T25) -> 3 | X25: =COUNTIF(D$18:D$254,$T25) -> 2 | Y25: =COUNTIF(E$18:E$254,$T25) -> 4 | AB25: =T20 -> P3 | AC25: 4 | AD25: =IF(_xlfn.XLOOKUP($AC25,$AR$18:$AR$22,AS$18:AS$22)=1, _xlfn.XLOOKUP($AB25,$T$18:$T$26,U$18:U$26)+U$25, IF(_xlfn.XLOOKUP($AC25,$AR$18:$AR$22,AS$18:AS$22)=0, U$27-(_xlfn.XLOOKUP($AB25,$T$18:$T$26,U$18:U$26)+U$25), U$27)) -> 11 | AE25: =IF(_xlfn.XLOOKUP($AC25,$AR$18:$AR$22,AT$18:AT$22)=1, _xlfn.XLOOKUP($AB25,$T$18:$T$26,V$18:V$26)+V$25, IF(_xlfn.XLOOKUP($AC25,$AR$18:$AR$22,AT$18:AT$22)=0, V$27-(_xlfn.XLOOKUP($AB25,$T$18:$T$26,V$18:V$26)+V$25), V$27)) -> 14 | AF25: =IF(_xlfn.XLOOKUP($AC25,$AR$18:$AR$22,AU$18:AU$22)=1, _xlfn.XLOOKUP($AB25,$T$18:$T$26,W$18:W$26)+W$25, IF(_xlfn.XLOOKUP($AC25,$AR$18:$AR$22,AU$18:AU$22)=0, W$27-(_xlfn.XLOOKUP($AB25,$T$18:$T$26,W$18:W$26)+W$25), W$27)) -> 13 | AG25: =IF(_xlfn.XLOOKUP($AC25,$AR$18:$AR$22,AV$18:AV$22)=1, _xlfn.XLOOKUP($AB25,$T$18:$T$26,X$18:X$26)+X$25, IF(_xlfn.XLOOKUP($AC25,$AR$18:$AR$22,AV$18:AV$22)=0, X$27-(_xlfn.XLOOKUP($AB25,$T$18:$T$26,X$18:X$26)+X$25), X$27)) -> 15 | AH25: =IF(_xlfn.XLOOKUP($AC25,$AR$18:$AR$22,AW$18:AW$22)=1, _xlfn.XLOOKUP($AB25,$T$18:$T$26,Y$18:Y$26)+Y$25, IF(_xlfn.XLOOKUP($AC25,$AR$18:$AR$22,AW$18:AW$22)=0, Y$27-(_xlfn.XLOOKUP($AB25,$T$18:$T$26,Y$18:Y$26)+Y$25), Y$27)) -> 64 | AI25: =PRODUCT(AD25:AH25) -> 1921920 | AJ25: =AI25/$U$28 -> 0.00058240803 | AK25: =1/AJ25 -> 1717.0093 | AL25: =IFERROR(INDEX(Summary!$C$4:$E$9, MATCH($AB25, Summary!$B$4:$B$9, 0), MATCH($AC25, Summary!$C$3:$E$3, 0)), 0) -> 50
A26: P4 | B26: P5 | C26: WILD | D26: CP | E26: P5 | H26: {=IF(ROW(A26)-H$15 < H$14,A26,IF(ROW(A26) - H$15 -H$16 + 1 < H$14,INDIRECT(ADDRESS(MOD(ROW(A26) - H$15, H$14) + H$15, COLUMN(A26))),""))} -> P4 | I26: {=IF(ROW(B26)-I$15 < I$14,B26,IF(ROW(B26) - I$15 -I$16 + 1 < I$14,INDIRECT(ADDRESS(MOD(ROW(B26) - I$15, I$14) + I$15, COLUMN(B26))),""))} -> P5 | J26: {=IF(ROW(C26)-J$15 < J$14,C26,IF(ROW(C26) - J$15 -J$16 + 1 < J$14,INDIRECT(ADDRESS(MOD(ROW(C26) - J$15, J$14) + J$15, COLUMN(C26))),""))} -> WILD | K26: {=IF(ROW(D26)-K$15 < K$14,D26,IF(ROW(D26) - K$15 -K$16 + 1 < K$14,INDIRECT(ADDRESS(MOD(ROW(D26) - K$15, K$14) + K$15, COLUMN(D26))),""))} -> CP | L26: {=IF(ROW(E26)-L$15 < L$14,E26,IF(ROW(E26) - L$15 -L$16 + 1 < L$14,INDIRECT(ADDRESS(MOD(ROW(E26) - L$15, L$14) + L$15, COLUMN(E26))),""))} -> P5 | N26: {=IF(H26<>"", SUMPRODUCT((OFFSET(H26,0,0,H$16,1)=$T$24) +0),"")} -> 0 | O26: {=IF(I26<>"", SUMPRODUCT((OFFSET(I26,0,0,I$16,1)=$T$24) +0),"")} -> 0 | P26: {=IF(J26<>"", SUMPRODUCT((OFFSET(J26,0,0,J$16,1)=$T$24) +0),"")} -> 0 | Q26: {=IF(K26<>"", SUMPRODUCT((OFFSET(K26,0,0,K$16,1)=$T$24) +0),"")} -> 2 | R26: {=IF(L26<>"", SUMPRODUCT((OFFSET(L26,0,0,L$16,1)=$T$24) +0),"")} -> 0 | T26: =Summary!B12 -> SCAT | U26: =COUNTIF(A$18:A$254,$T26) -> 5 | V26: =COUNTIF(B$18:B$254,$T26) -> 0 | W26: =COUNTIF(C$18:C$254,$T26) -> 5 | X26: =COUNTIF(D$18:D$254,$T26) -> 0 | Y26: =COUNTIF(E$18:E$254,$T26) -> 3 | AB26: =T20 -> P3 | AC26: 3 | AD26: =IF(_xlfn.XLOOKUP($AC26,$AR$18:$AR$22,AS$18:AS$22)=1, _xlfn.XLOOKUP($AB26,$T$18:$T$26,U$18:U$26)+U$25, IF(_xlfn.XLOOKUP($AC26,$AR$18:$AR$22,AS$18:AS$22)=0, U$27-(_xlfn.XLOOKUP($AB26,$T$18:$T$26,U$18:U$26)+U$25), U$27)) -> 11 | AE26: =IF(_xlfn.XLOOKUP($AC26,$AR$18:$AR$22,AT$18:AT$22)=1, _xlfn.XLOOKUP($AB26,$T$18:$T$26,V$18:V$26)+V$25, IF(_xlfn.XLOOKUP($AC26,$AR$18:$AR$22,AT$18:AT$22)=0, V$27-(_xlfn.XLOOKUP($AB26,$T$18:$T$26,V$18:V$26)+V$25), V$27)) -> 14 | AF26: =IF(_xlfn.XLOOKUP($AC26,$AR$18:$AR$22,AU$18:AU$22)=1, _xlfn.XLOOKUP($AB26,$T$18:$T$26,W$18:W$26)+W$25, IF(_xlfn.XLOOKUP($AC26,$AR$18:$AR$22,AU$18:AU$22)=0, W$27-(_xlfn.XLOOKUP($AB26,$T$18:$T$26,W$18:W$26)+W$25), W$27)) -> 13 | AG26: =IF(_xlfn.XLOOKUP($AC26,$AR$18:$AR$22,AV$18:AV$22)=1, _xlfn.XLOOKUP($AB26,$T$18:$T$26,X$18:X$26)+X$25, IF(_xlfn.XLOOKUP($AC26,$AR$18:$AR$22,AV$18:AV$22)=0, X$27-(_xlfn.XLOOKUP($AB26,$T$18:$T$26,X$18:X$26)+X$25), X$27)) -> 61 | AH26: =IF(_xlfn.XLOOKUP($AC26,$AR$18:$AR$22,AW$18:AW$22)=1, _xlfn.XLOOKUP($AB26,$T$18:$T$26,Y$18:Y$26)+Y$25, IF(_xlfn.XLOOKUP($AC26,$AR$18:$AR$22,AW$18:AW$22)=0, Y$27-(_xlfn.XLOOKUP($AB26,$T$18:$T$26,Y$18:Y$26)+Y$25), Y$27)) -> 77 | AI26: =PRODUCT(AD26:AH26) -> 9403394 | AJ26: =AI26/$U$28 -> 0.0028495526 | AK26: =1/AJ26 -> 350.93228 | AL26: =IFERROR(INDEX(Summary!$C$4:$E$9, MATCH($AB26, Summary!$B$4:$B$9, 0), MATCH($AC26, Summary!$C$3:$E$3, 0)), 0) -> 10
A27: P5 | B27: P3 | C27: P5 | D27: CP | E27: P4 | H27: {=IF(ROW(A27)-H$15 < H$14,A27,IF(ROW(A27) - H$15 -H$16 + 1 < H$14,INDIRECT(ADDRESS(MOD(ROW(A27) - H$15, H$14) + H$15, COLUMN(A27))),""))} -> P5 | I27: {=IF(ROW(B27)-I$15 < I$14,B27,IF(ROW(B27) - I$15 -I$16 + 1 < I$14,INDIRECT(ADDRESS(MOD(ROW(B27) - I$15, I$14) + I$15, COLUMN(B27))),""))} -> P3 | J27: {=IF(ROW(C27)-J$15 < J$14,C27,IF(ROW(C27) - J$15 -J$16 + 1 < J$14,INDIRECT(ADDRESS(MOD(ROW(C27) - J$15, J$14) + J$15, COLUMN(C27))),""))} -> P5 | K27: {=IF(ROW(D27)-K$15 < K$14,D27,IF(ROW(D27) - K$15 -K$16 + 1 < K$14,INDIRECT(ADDRESS(MOD(ROW(D27) - K$15, K$14) + K$15, COLUMN(D27))),""))} -> CP | L27: {=IF(ROW(E27)-L$15 < L$14,E27,IF(ROW(E27) - L$15 -L$16 + 1 < L$14,INDIRECT(ADDRESS(MOD(ROW(E27) - L$15, L$14) + L$15, COLUMN(E27))),""))} -> P4 | N27: {=IF(H27<>"", SUMPRODUCT((OFFSET(H27,0,0,H$16,1)=$T$24) +0),"")} -> 0 | O27: {=IF(I27<>"", SUMPRODUCT((OFFSET(I27,0,0,I$16,1)=$T$24) +0),"")} -> 0 | P27: {=IF(J27<>"", SUMPRODUCT((OFFSET(J27,0,0,J$16,1)=$T$24) +0),"")} -> 0 | Q27: {=IF(K27<>"", SUMPRODUCT((OFFSET(K27,0,0,K$16,1)=$T$24) +0),"")} -> 1 | R27: {=IF(L27<>"", SUMPRODUCT((OFFSET(L27,0,0,L$16,1)=$T$24) +0),"")} -> 0 | T27: SUM | U27: =SUM(U18:U26) -> 83 | V27: =SUM(V18:V26) -> 79 | W27: =SUM(W18:W26) -> 86 | X27: =SUM(X18:X26) -> 76 | Y27: =SUM(Y18:Y26) -> 77 | AB27: =T21 -> P4 | AC27: 5 | AD27: =IF(_xlfn.XLOOKUP($AC27,$AR$18:$AR$22,AS$18:AS$22)=1, _xlfn.XLOOKUP($AB27,$T$18:$T$26,U$18:U$26)+U$25, IF(_xlfn.XLOOKUP($AC27,$AR$18:$AR$22,AS$18:AS$22)=0, U$27-(_xlfn.XLOOKUP($AB27,$T$18:$T$26,U$18:U$26)+U$25), U$27)) -> 14 | AE27: =IF(_xlfn.XLOOKUP($AC27,$AR$18:$AR$22,AT$18:AT$22)=1, _xlfn.XLOOKUP($AB27,$T$18:$T$26,V$18:V$26)+V$25, IF(_xlfn.XLOOKUP($AC27,$AR$18:$AR$22,AT$18:AT$22)=0, V$27-(_xlfn.XLOOKUP($AB27,$T$18:$T$26,V$18:V$26)+V$25), V$27)) -> 17 | AF27: =IF(_xlfn.XLOOKUP($AC27,$AR$18:$AR$22,AU$18:AU$22)=1, _xlfn.XLOOKUP($AB27,$T$18:$T$26,W$18:W$26)+W$25, IF(_xlfn.XLOOKUP($AC27,$AR$18:$AR$22,AU$18:AU$22)=0, W$27-(_xlfn.XLOOKUP($AB27,$T$18:$T$26,W$18:W$26)+W$25), W$27)) -> 15 | AG27: =IF(_xlfn.XLOOKUP($AC27,$AR$18:$AR$22,AV$18:AV$22)=1, _xlfn.XLOOKUP($AB27,$T$18:$T$26,X$18:X$26)+X$25, IF(_xlfn.XLOOKUP($AC27,$AR$18:$AR$22,AV$18:AV$22)=0, X$27-(_xlfn.XLOOKUP($AB27,$T$18:$T$26,X$18:X$26)+X$25), X$27)) -> 16 | AH27: =IF(_xlfn.XLOOKUP($AC27,$AR$18:$AR$22,AW$18:AW$22)=1, _xlfn.XLOOKUP($AB27,$T$18:$T$26,Y$18:Y$26)+Y$25, IF(_xlfn.XLOOKUP($AC27,$AR$18:$AR$22,AW$18:AW$22)=0, Y$27-(_xlfn.XLOOKUP($AB27,$T$18:$T$26,Y$18:Y$26)+Y$25), Y$27)) -> 16 | AI27: =PRODUCT(AD27:AH27) -> 913920 | AJ27: =AI27/$U$28 -> 0.00027694927 | AK27: =1/AJ27 -> 3610.7695 | AL27: =IFERROR(INDEX(Summary!$C$4:$E$9, MATCH($AB27, Summary!$B$4:$B$9, 0), MATCH($AC27, Summary!$C$3:$E$3, 0)), 0) -> 100 | AM27: =SUM(AJ27*AL27,AJ28*AL28,AJ29*AL29) -> 0.079081999
A28: P5 | B28: P4 | C28: P4 | D28: P5 | E28: P2 | H28: {=IF(ROW(A28)-H$15 < H$14,A28,IF(ROW(A28) - H$15 -H$16 + 1 < H$14,INDIRECT(ADDRESS(MOD(ROW(A28) - H$15, H$14) + H$15, COLUMN(A28))),""))} -> P5 | I28: {=IF(ROW(B28)-I$15 < I$14,B28,IF(ROW(B28) - I$15 -I$16 + 1 < I$14,INDIRECT(ADDRESS(MOD(ROW(B28) - I$15, I$14) + I$15, COLUMN(B28))),""))} -> P4 | J28: {=IF(ROW(C28)-J$15 < J$14,C28,IF(ROW(C28) - J$15 -J$16 + 1 < J$14,INDIRECT(ADDRESS(MOD(ROW(C28) - J$15, J$14) + J$15, COLUMN(C28))),""))} -> P4 | K28: {=IF(ROW(D28)-K$15 < K$14,D28,IF(ROW(D28) - K$15 -K$16 + 1 < K$14,INDIRECT(ADDRESS(MOD(ROW(D28) - K$15, K$14) + K$15, COLUMN(D28))),""))} -> P5 | L28: {=IF(ROW(E28)-L$15 < L$14,E28,IF(ROW(E28) - L$15 -L$16 + 1 < L$14,INDIRECT(ADDRESS(MOD(ROW(E28) - L$15, L$14) + L$15, COLUMN(E28))),""))} -> P2 | N28: {=IF(H28<>"", SUMPRODUCT((OFFSET(H28,0,0,H$16,1)=$T$24) +0),"")} -> 0 | O28: {=IF(I28<>"", SUMPRODUCT((OFFSET(I28,0,0,I$16,1)=$T$24) +0),"")} -> 0 | P28: {=IF(J28<>"", SUMPRODUCT((OFFSET(J28,0,0,J$16,1)=$T$24) +0),"")} -> 0 | Q28: {=IF(K28<>"", SUMPRODUCT((OFFSET(K28,0,0,K$16,1)=$T$24) +0),"")} -> 0 | R28: {=IF(L28<>"", SUMPRODUCT((OFFSET(L28,0,0,L$16,1)=$T$24) +0),"")} -> 0 | T28: PRODUCT | U28: =PRODUCT(U27:Z27) -> 3299954504 | AB28: =T21 -> P4 | AC28: 4 | AD28: =IF(_xlfn.XLOOKUP($AC28,$AR$18:$AR$22,AS$18:AS$22)=1, _xlfn.XLOOKUP($AB28,$T$18:$T$26,U$18:U$26)+U$25, IF(_xlfn.XLOOKUP($AC28,$AR$18:$AR$22,AS$18:AS$22)=0, U$27-(_xlfn.XLOOKUP($AB28,$T$18:$T$26,U$18:U$26)+U$25), U$27)) -> 14 | AE28: =IF(_xlfn.XLOOKUP($AC28,$AR$18:$AR$22,AT$18:AT$22)=1, _xlfn.XLOOKUP($AB28,$T$18:$T$26,V$18:V$26)+V$25, IF(_xlfn.XLOOKUP($AC28,$AR$18:$AR$22,AT$18:AT$22)=0, V$27-(_xlfn.XLOOKUP($AB28,$T$18:$T$26,V$18:V$26)+V$25), V$27)) -> 17 | AF28: =IF(_xlfn.XLOOKUP($AC28,$AR$18:$AR$22,AU$18:AU$22)=1, _xlfn.XLOOKUP($AB28,$T$18:$T$26,W$18:W$26)+W$25, IF(_xlfn.XLOOKUP($AC28,$AR$18:$AR$22,AU$18:AU$22)=0, W$27-(_xlfn.XLOOKUP($AB28,$T$18:$T$26,W$18:W$26)+W$25), W$27)) -> 15 | AG28: =IF(_xlfn.XLOOKUP($AC28,$AR$18:$AR$22,AV$18:AV$22)=1, _xlfn.XLOOKUP($AB28,$T$18:$T$26,X$18:X$26)+X$25, IF(_xlfn.XLOOKUP($AC28,$AR$18:$AR$22,AV$18:AV$22)=0, X$27-(_xlfn.XLOOKUP($AB28,$T$18:$T$26,X$18:X$26)+X$25), X$27)) -> 16 | AH28: =IF(_xlfn.XLOOKUP($AC28,$AR$18:$AR$22,AW$18:AW$22)=1, _xlfn.XLOOKUP($AB28,$T$18:$T$26,Y$18:Y$26)+Y$25, IF(_xlfn.XLOOKUP($AC28,$AR$18:$AR$22,AW$18:AW$22)=0, Y$27-(_xlfn.XLOOKUP($AB28,$T$18:$T$26,Y$18:Y$26)+Y$25), Y$27)) -> 61 | AI28: =PRODUCT(AD28:AH28) -> 3484320 | AJ28: =AI28/$U$28 -> 0.0010558691 | AK28: =1/AJ28 -> 947.08709 | AL28: =IFERROR(INDEX(Summary!$C$4:$E$9, MATCH($AB28, Summary!$B$4:$B$9, 0), MATCH($AC28, Summary!$C$3:$E$3, 0)), 0) -> 25
A29: P4 | B29: P6 | C29: P6 | D29: P6 | E29: P5 | H29: {=IF(ROW(A29)-H$15 < H$14,A29,IF(ROW(A29) - H$15 -H$16 + 1 < H$14,INDIRECT(ADDRESS(MOD(ROW(A29) - H$15, H$14) + H$15, COLUMN(A29))),""))} -> P4 | I29: {=IF(ROW(B29)-I$15 < I$14,B29,IF(ROW(B29) - I$15 -I$16 + 1 < I$14,INDIRECT(ADDRESS(MOD(ROW(B29) - I$15, I$14) + I$15, COLUMN(B29))),""))} -> P6 | J29: {=IF(ROW(C29)-J$15 < J$14,C29,IF(ROW(C29) - J$15 -J$16 + 1 < J$14,INDIRECT(ADDRESS(MOD(ROW(C29) - J$15, J$14) + J$15, COLUMN(C29))),""))} -> P6 | K29: {=IF(ROW(D29)-K$15 < K$14,D29,IF(ROW(D29) - K$15 -K$16 + 1 < K$14,INDIRECT(ADDRESS(MOD(ROW(D29) - K$15, K$14) + K$15, COLUMN(D29))),""))} -> P6 | L29: {=IF(ROW(E29)-L$15 < L$14,E29,IF(ROW(E29) - L$15 -L$16 + 1 < L$14,INDIRECT(ADDRESS(MOD(ROW(E29) - L$15, L$14) + L$15, COLUMN(E29))),""))} -> P5 | N29: {=IF(H29<>"", SUMPRODUCT((OFFSET(H29,0,0,H$16,1)=$T$24) +0),"")} -> 0 | O29: {=IF(I29<>"", SUMPRODUCT((OFFSET(I29,0,0,I$16,1)=$T$24) +0),"")} -> 0 | P29: {=IF(J29<>"", SUMPRODUCT((OFFSET(J29,0,0,J$16,1)=$T$24) +0),"")} -> 0 | Q29: {=IF(K29<>"", SUMPRODUCT((OFFSET(K29,0,0,K$16,1)=$T$24) +0),"")} -> 0 | R29: {=IF(L29<>"", SUMPRODUCT((OFFSET(L29,0,0,L$16,1)=$T$24) +0),"")} -> 0 | AB29: =T21 -> P4 | AC29: 3 | AD29: =IF(_xlfn.XLOOKUP($AC29,$AR$18:$AR$22,AS$18:AS$22)=1, _xlfn.XLOOKUP($AB29,$T$18:$T$26,U$18:U$26)+U$25, IF(_xlfn.XLOOKUP($AC29,$AR$18:$AR$22,AS$18:AS$22)=0, U$27-(_xlfn.XLOOKUP($AB29,$T$18:$T$26,U$18:U$26)+U$25), U$27)) -> 14 | AE29: =IF(_xlfn.XLOOKUP($AC29,$AR$18:$AR$22,AT$18:AT$22)=1, _xlfn.XLOOKUP($AB29,$T$18:$T$26,V$18:V$26)+V$25, IF(_xlfn.XLOOKUP($AC29,$AR$18:$AR$22,AT$18:AT$22)=0, V$27-(_xlfn.XLOOKUP($AB29,$T$18:$T$26,V$18:V$26)+V$25), V$27)) -> 17 | AF29: =IF(_xlfn.XLOOKUP($AC29,$AR$18:$AR$22,AU$18:AU$22)=1, _xlfn.XLOOKUP($AB29,$T$18:$T$26,W$18:W$26)+W$25, IF(_xlfn.XLOOKUP($AC29,$AR$18:$AR$22,AU$18:AU$22)=0, W$27-(_xlfn.XLOOKUP($AB29,$T$18:$T$26,W$18:W$26)+W$25), W$27)) -> 15 | AG29: =IF(_xlfn.XLOOKUP($AC29,$AR$18:$AR$22,AV$18:AV$22)=1, _xlfn.XLOOKUP($AB29,$T$18:$T$26,X$18:X$26)+X$25, IF(_xlfn.XLOOKUP($AC29,$AR$18:$AR$22,AV$18:AV$22)=0, X$27-(_xlfn.XLOOKUP($AB29,$T$18:$T$26,X$18:X$26)+X$25), X$27)) -> 60 | AH29: =IF(_xlfn.XLOOKUP($AC29,$AR$18:$AR$22,AW$18:AW$22)=1, _xlfn.XLOOKUP($AB29,$T$18:$T$26,Y$18:Y$26)+Y$25, IF(_xlfn.XLOOKUP($AC29,$AR$18:$AR$22,AW$18:AW$22)=0, Y$27-(_xlfn.XLOOKUP($AB29,$T$18:$T$26,Y$18:Y$26)+Y$25), Y$27)) -> 77 | AI29: =PRODUCT(AD29:AH29) -> 16493400 | AJ29: =AI29/$U$28 -> 0.0049980689 | AK29: =1/AJ29 -> 200.07727 | AL29: =IFERROR(INDEX(Summary!$C$4:$E$9, MATCH($AB29, Summary!$B$4:$B$9, 0), MATCH($AC29, Summary!$C$3:$E$3, 0)), 0) -> 5
A30: P5 | B30: WILD | C30: P6 | D30: P6 | E30: WILD | H30: {=IF(ROW(A30)-H$15 < H$14,A30,IF(ROW(A30) - H$15 -H$16 + 1 < H$14,INDIRECT(ADDRESS(MOD(ROW(A30) - H$15, H$14) + H$15, COLUMN(A30))),""))} -> P5 | I30: {=IF(ROW(B30)-I$15 < I$14,B30,IF(ROW(B30) - I$15 -I$16 + 1 < I$14,INDIRECT(ADDRESS(MOD(ROW(B30) - I$15, I$14) + I$15, COLUMN(B30))),""))} -> WILD | J30: {=IF(ROW(C30)-J$15 < J$14,C30,IF(ROW(C30) - J$15 -J$16 + 1 < J$14,INDIRECT(ADDRESS(MOD(ROW(C30) - J$15, J$14) + J$15, COLUMN(C30))),""))} -> P6 | K30: {=IF(ROW(D30)-K$15 < K$14,D30,IF(ROW(D30) - K$15 -K$16 + 1 < K$14,INDIRECT(ADDRESS(MOD(ROW(D30) - K$15, K$14) + K$15, COLUMN(D30))),""))} -> P6 | L30: {=IF(ROW(E30)-L$15 < L$14,E30,IF(ROW(E30) - L$15 -L$16 + 1 < L$14,INDIRECT(ADDRESS(MOD(ROW(E30) - L$15, L$14) + L$15, COLUMN(E30))),""))} -> WILD | N30: {=IF(H30<>"", SUMPRODUCT((OFFSET(H30,0,0,H$16,1)=$T$24) +0),"")} -> 0 | O30: {=IF(I30<>"", SUMPRODUCT((OFFSET(I30,0,0,I$16,1)=$T$24) +0),"")} -> 0 | P30: {=IF(J30<>"", SUMPRODUCT((OFFSET(J30,0,0,J$16,1)=$T$24) +0),"")} -> 0 | Q30: {=IF(K30<>"", SUMPRODUCT((OFFSET(K30,0,0,K$16,1)=$T$24) +0),"")} -> 0 | R30: {=IF(L30<>"", SUMPRODUCT((OFFSET(L30,0,0,L$16,1)=$T$24) +0),"")} -> 0 | AB30: =T22 -> P5 | AC30: 5 | AD30: =IF(_xlfn.XLOOKUP($AC30,$AR$18:$AR$22,AS$18:AS$22)=1, _xlfn.XLOOKUP($AB30,$T$18:$T$26,U$18:U$26)+U$25, IF(_xlfn.XLOOKUP($AC30,$AR$18:$AR$22,AS$18:AS$22)=0, U$27-(_xlfn.XLOOKUP($AB30,$T$18:$T$26,U$18:U$26)+U$25), U$27)) -> 14 | AE30: =IF(_xlfn.XLOOKUP($AC30,$AR$18:$AR$22,AT$18:AT$22)=1, _xlfn.XLOOKUP($AB30,$T$18:$T$26,V$18:V$26)+V$25, IF(_xlfn.XLOOKUP($AC30,$AR$18:$AR$22,AT$18:AT$22)=0, V$27-(_xlfn.XLOOKUP($AB30,$T$18:$T$26,V$18:V$26)+V$25), V$27)) -> 15 | AF30: =IF(_xlfn.XLOOKUP($AC30,$AR$18:$AR$22,AU$18:AU$22)=1, _xlfn.XLOOKUP($AB30,$T$18:$T$26,W$18:W$26)+W$25, IF(_xlfn.XLOOKUP($AC30,$AR$18:$AR$22,AU$18:AU$22)=0, W$27-(_xlfn.XLOOKUP($AB30,$T$18:$T$26,W$18:W$26)+W$25), W$27)) -> 16 | AG30: =IF(_xlfn.XLOOKUP($AC30,$AR$18:$AR$22,AV$18:AV$22)=1, _xlfn.XLOOKUP($AB30,$T$18:$T$26,X$18:X$26)+X$25, IF(_xlfn.XLOOKUP($AC30,$AR$18:$AR$22,AV$18:AV$22)=0, X$27-(_xlfn.XLOOKUP($AB30,$T$18:$T$26,X$18:X$26)+X$25), X$27)) -> 15 | AH30: =IF(_xlfn.XLOOKUP($AC30,$AR$18:$AR$22,AW$18:AW$22)=1, _xlfn.XLOOKUP($AB30,$T$18:$T$26,Y$18:Y$26)+Y$25, IF(_xlfn.XLOOKUP($AC30,$AR$18:$AR$22,AW$18:AW$22)=0, Y$27-(_xlfn.XLOOKUP($AB30,$T$18:$T$26,Y$18:Y$26)+Y$25), Y$27)) -> 17 | AI30: =PRODUCT(AD30:AH30) -> 856800 | AJ30: =AI30/$U$28 -> 0.00025963994 | AK30: =1/AJ30 -> 3851.4875 | AL30: =IFERROR(INDEX(Summary!$C$4:$E$9, MATCH($AB30, Summary!$B$4:$B$9, 0), MATCH($AC30, Summary!$C$3:$E$3, 0)), 0) -> 100 | AM30: =SUM(AJ30*AL30,AJ31*AL31,AJ32*AL32) -> 0.072785731
A31: SCAT | B31: P5 | C31: P2 | D31: P3 | E31: P6 | H31: {=IF(ROW(A31)-H$15 < H$14,A31,IF(ROW(A31) - H$15 -H$16 + 1 < H$14,INDIRECT(ADDRESS(MOD(ROW(A31) - H$15, H$14) + H$15, COLUMN(A31))),""))} -> SCAT | I31: {=IF(ROW(B31)-I$15 < I$14,B31,IF(ROW(B31) - I$15 -I$16 + 1 < I$14,INDIRECT(ADDRESS(MOD(ROW(B31) - I$15, I$14) + I$15, COLUMN(B31))),""))} -> P5 | J31: {=IF(ROW(C31)-J$15 < J$14,C31,IF(ROW(C31) - J$15 -J$16 + 1 < J$14,INDIRECT(ADDRESS(MOD(ROW(C31) - J$15, J$14) + J$15, COLUMN(C31))),""))} -> P2 | K31: {=IF(ROW(D31)-K$15 < K$14,D31,IF(ROW(D31) - K$15 -K$16 + 1 < K$14,INDIRECT(ADDRESS(MOD(ROW(D31) - K$15, K$14) + K$15, COLUMN(D31))),""))} -> P3 | L31: {=IF(ROW(E31)-L$15 < L$14,E31,IF(ROW(E31) - L$15 -L$16 + 1 < L$14,INDIRECT(ADDRESS(MOD(ROW(E31) - L$15, L$14) + L$15, COLUMN(E31))),""))} -> P6 | N31: {=IF(H31<>"", SUMPRODUCT((OFFSET(H31,0,0,H$16,1)=$T$24) +0),"")} -> 0 | O31: {=IF(I31<>"", SUMPRODUCT((OFFSET(I31,0,0,I$16,1)=$T$24) +0),"")} -> 0 | P31: {=IF(J31<>"", SUMPRODUCT((OFFSET(J31,0,0,J$16,1)=$T$24) +0),"")} -> 0 | Q31: {=IF(K31<>"", SUMPRODUCT((OFFSET(K31,0,0,K$16,1)=$T$24) +0),"")} -> 0 | R31: {=IF(L31<>"", SUMPRODUCT((OFFSET(L31,0,0,L$16,1)=$T$24) +0),"")} -> 0 | AB31: =T22 -> P5 | AC31: 4 | AD31: =IF(_xlfn.XLOOKUP($AC31,$AR$18:$AR$22,AS$18:AS$22)=1, _xlfn.XLOOKUP($AB31,$T$18:$T$26,U$18:U$26)+U$25, IF(_xlfn.XLOOKUP($AC31,$AR$18:$AR$22,AS$18:AS$22)=0, U$27-(_xlfn.XLOOKUP($AB31,$T$18:$T$26,U$18:U$26)+U$25), U$27)) -> 14 | AE31: =IF(_xlfn.XLOOKUP($AC31,$AR$18:$AR$22,AT$18:AT$22)=1, _xlfn.XLOOKUP($AB31,$T$18:$T$26,V$18:V$26)+V$25, IF(_xlfn.XLOOKUP($AC31,$AR$18:$AR$22,AT$18:AT$22)=0, V$27-(_xlfn.XLOOKUP($AB31,$T$18:$T$26,V$18:V$26)+V$25), V$27)) -> 15 | AF31: =IF(_xlfn.XLOOKUP($AC31,$AR$18:$AR$22,AU$18:AU$22)=1, _xlfn.XLOOKUP($AB31,$T$18:$T$26,W$18:W$26)+W$25, IF(_xlfn.XLOOKUP($AC31,$AR$18:$AR$22,AU$18:AU$22)=0, W$27-(_xlfn.XLOOKUP($AB31,$T$18:$T$26,W$18:W$26)+W$25), W$27)) -> 16 | AG31: =IF(_xlfn.XLOOKUP($AC31,$AR$18:$AR$22,AV$18:AV$22)=1, _xlfn.XLOOKUP($AB31,$T$18:$T$26,X$18:X$26)+X$25, IF(_xlfn.XLOOKUP($AC31,$AR$18:$AR$22,AV$18:AV$22)=0, X$27-(_xlfn.XLOOKUP($AB31,$T$18:$T$26,X$18:X$26)+X$25), X$27)) -> 15 | AH31: =IF(_xlfn.XLOOKUP($AC31,$AR$18:$AR$22,AW$18:AW$22)=1, _xlfn.XLOOKUP($AB31,$T$18:$T$26,Y$18:Y$26)+Y$25, IF(_xlfn.XLOOKUP($AC31,$AR$18:$AR$22,AW$18:AW$22)=0, Y$27-(_xlfn.XLOOKUP($AB31,$T$18:$T$26,Y$18:Y$26)+Y$25), Y$27)) -> 60 | AI31: =PRODUCT(AD31:AH31) -> 3024000 | AJ31: =AI31/$U$28 -> 0.00091637627 | AK31: =1/AJ31 -> 1091.2548 | AL31: =IFERROR(INDEX(Summary!$C$4:$E$9, MATCH($AB31, Summary!$B$4:$B$9, 0), MATCH($AC31, Summary!$C$3:$E$3, 0)), 0) -> 25
A32: P6 | B32: P3 | C32: P5 | D32: P4 | E32: P1 | H32: {=IF(ROW(A32)-H$15 < H$14,A32,IF(ROW(A32) - H$15 -H$16 + 1 < H$14,INDIRECT(ADDRESS(MOD(ROW(A32) - H$15, H$14) + H$15, COLUMN(A32))),""))} -> P6 | I32: {=IF(ROW(B32)-I$15 < I$14,B32,IF(ROW(B32) - I$15 -I$16 + 1 < I$14,INDIRECT(ADDRESS(MOD(ROW(B32) - I$15, I$14) + I$15, COLUMN(B32))),""))} -> P3 | J32: {=IF(ROW(C32)-J$15 < J$14,C32,IF(ROW(C32) - J$15 -J$16 + 1 < J$14,INDIRECT(ADDRESS(MOD(ROW(C32) - J$15, J$14) + J$15, COLUMN(C32))),""))} -> P5 | K32: {=IF(ROW(D32)-K$15 < K$14,D32,IF(ROW(D32) - K$15 -K$16 + 1 < K$14,INDIRECT(ADDRESS(MOD(ROW(D32) - K$15, K$14) + K$15, COLUMN(D32))),""))} -> P4 | L32: {=IF(ROW(E32)-L$15 < L$14,E32,IF(ROW(E32) - L$15 -L$16 + 1 < L$14,INDIRECT(ADDRESS(MOD(ROW(E32) - L$15, L$14) + L$15, COLUMN(E32))),""))} -> P1 | N32: {=IF(H32<>"", SUMPRODUCT((OFFSET(H32,0,0,H$16,1)=$T$24) +0),"")} -> 0 | O32: {=IF(I32<>"", SUMPRODUCT((OFFSET(I32,0,0,I$16,1)=$T$24) +0),"")} -> 1 | P32: {=IF(J32<>"", SUMPRODUCT((OFFSET(J32,0,0,J$16,1)=$T$24) +0),"")} -> 0 | Q32: {=IF(K32<>"", SUMPRODUCT((OFFSET(K32,0,0,K$16,1)=$T$24) +0),"")} -> 0 | R32: {=IF(L32<>"", SUMPRODUCT((OFFSET(L32,0,0,L$16,1)=$T$24) +0),"")} -> 0 | AB32: =T22 -> P5 | AC32: 3 | AD32: =IF(_xlfn.XLOOKUP($AC32,$AR$18:$AR$22,AS$18:AS$22)=1, _xlfn.XLOOKUP($AB32,$T$18:$T$26,U$18:U$26)+U$25, IF(_xlfn.XLOOKUP($AC32,$AR$18:$AR$22,AS$18:AS$22)=0, U$27-(_xlfn.XLOOKUP($AB32,$T$18:$T$26,U$18:U$26)+U$25), U$27)) -> 14 | AE32: =IF(_xlfn.XLOOKUP($AC32,$AR$18:$AR$22,AT$18:AT$22)=1, _xlfn.XLOOKUP($AB32,$T$18:$T$26,V$18:V$26)+V$25, IF(_xlfn.XLOOKUP($AC32,$AR$18:$AR$22,AT$18:AT$22)=0, V$27-(_xlfn.XLOOKUP($AB32,$T$18:$T$26,V$18:V$26)+V$25), V$27)) -> 15 | AF32: =IF(_xlfn.XLOOKUP($AC32,$AR$18:$AR$22,AU$18:AU$22)=1, _xlfn.XLOOKUP($AB32,$T$18:$T$26,W$18:W$26)+W$25, IF(_xlfn.XLOOKUP($AC32,$AR$18:$AR$22,AU$18:AU$22)=0, W$27-(_xlfn.XLOOKUP($AB32,$T$18:$T$26,W$18:W$26)+W$25), W$27)) -> 16 | AG32: =IF(_xlfn.XLOOKUP($AC32,$AR$18:$AR$22,AV$18:AV$22)=1, _xlfn.XLOOKUP($AB32,$T$18:$T$26,X$18:X$26)+X$25, IF(_xlfn.XLOOKUP($AC32,$AR$18:$AR$22,AV$18:AV$22)=0, X$27-(_xlfn.XLOOKUP($AB32,$T$18:$T$26,X$18:X$26)+X$25), X$27)) -> 61 | AH32: =IF(_xlfn.XLOOKUP($AC32,$AR$18:$AR$22,AW$18:AW$22)=1, _xlfn.XLOOKUP($AB32,$T$18:$T$26,Y$18:Y$26)+Y$25, IF(_xlfn.XLOOKUP($AC32,$AR$18:$AR$22,AW$18:AW$22)=0, Y$27-(_xlfn.XLOOKUP($AB32,$T$18:$T$26,Y$18:Y$26)+Y$25), Y$27)) -> 77 | AI32: =PRODUCT(AD32:AH32) -> 15781920 | AJ32: =AI32/$U$28 -> 0.0047824659 | AK32: =1/AJ32 -> 209.09715 | AL32: =IFERROR(INDEX(Summary!$C$4:$E$9, MATCH($AB32, Summary!$B$4:$B$9, 0), MATCH($AC32, Summary!$C$3:$E$3, 0)), 0) -> 5
